Workbook

Sheet How to use
A1: Turo Fleet Tracker — path to $300k/yr net
A2: Educational tool only. Not financial, tax or legal advice. Verify insurance, tax and permits locally.
A4: Step 1 | B4: Assumptions tab: set your goal, start month and targets (yellow cells).
A5: Step 2 | B5: Fleet tab: one row per car. Fixed monthly costs (loan, insurance, registration, tracker, parking) go here — NOT in Expenses.
A6: Step 3 | B6: Trips tab: log every trip from your Turo earnings export. Days, host share, earnings and month fill in automatically.
A7: Step 4 | B7: Expenses tab: log variable costs (maintenance, tires, repairs, supplies, software). Use Car ID 'FLEET' for overhead.
A8: Step 5 | B8: Each month: move the Report month on Assumptions forward, then check Car Scorecard and see each car's net, utilization and payback. Cut any car flagged '3 losing months'.
A9: Step 6 | B9: Dashboard: 12-month P&L, run-rate and how many cars you need at today's net per car.
A10: Step 7 | B10: Buy Box: test a car before you buy it. Only buy 'BUY' verdicts.
A12: Colour legend
A13: Blue text, pale yellow fill | B13: Inputs you type in.
A14: Bright yellow fill | B14: Key assumptions that drive the whole workbook.
A15: Black text | B15: Formulas — do not overwrite.
A16: Green text | B16: Pulled from another tab.
A18: Example rows | B18: Rows whose Notes say 'EXAMPLE – delete' show the expected format. Clear them before you start.
A19: Trip timing | B19: Trips are counted in the month they START. A trip spanning month-end counts fully in the start month.
A20: Host share | B20: Trips use the car's earnings-plan share from Fleet; if blank, the default on Assumptions. US plans pay 70/80/90% of trip price (Turo help centre, Jan 2026) — re-check, Turo changes terms.
A21: Not modelled | B21: Depreciation / resale value, income tax, owner's time. Track resale value separately when you sell a car.

Sheet Dashboard
A1: Dashboard — 12-month P&L
A2: All figures are formulas. Trips count in the month they start.
A4: Annual goal | C4: Net profit (12 mo) | E4: % of goal | G4: Report-month run-rate | I4: Cars owned (that month) | K4: Cars needed at that net/car | M4: Cash reserve to hold
A5: =Assumptions!$B$4 -> 300000 | C5: =K22 -> -293.2 | E5: =IF(Assumptions!$B$4=0,0,K22/Assumptions!$B$4) -> -0.00097733333 | G5: =IFERROR(INDEX(M10:M21,MATCH(Assumptions!$B$6,A10:A21,0)),0) -> -3518.4 | I5: =IFERROR(INDEX(B10:B21,MATCH(Assumptions!$B$6,A10:A21,0)),0) -> 2 | K5: =IFERROR(INDEX(N10:N21,MATCH(Assumptions!$B$6,A10:A21,0)),"n/a") -> n/a | M5: =IFERROR(INDEX(B10:B21,MATCH(Assumptions!$B$6,A10:A21,0))*Assumptions!$B$11*(INDEX(I10:I21,MATCH(Assumptions!$B$6,A10:A21,0))+INDEX(J10:J21,MATCH(Assumptions!$B$6,A10:A21,0)))/MAX(1,INDEX(B10:B21,MATCH(Assumptions!$B$6,A10:A21,0))),0) -> 2576
A7: Rows show months up to the Report month (Assumptions tab). Tiles use the Report month. Cars bought mid-month carry a full month of fixed cost.
A9: Month | B9: Cars owned | C9: Available car-days | D9: Booked days | E9: Utilization | F9: Trips | G9: Gross trip price ($) | H9: Earnings + extras ($) | I9: Variable costs ($) | J9: Fixed costs ($) | K9: Net profit ($) | L9: Net per car ($) | M9: Annualized run-rate ($) | N9: Cars needed for goal (at this net/car)
A10: =Assumptions!$B$5 -> 46327 | B10: =IF($A10>Assumptions!$B$6,"",SUMPRODUCT(((Fleet!$A$5:$A$79<>"")*(Fleet!$E$5:$E$79<=EOMONTH($A10,0))*(((Fleet!$F$5:$F$79="")+(Fleet!$F$5:$F$79>=$A10))>0)))) -> 2 | C10: =IF($A10>Assumptions!$B$6,"",B10*DAY(EOMONTH($A10,0))) -> 60 | D10: =IF($A10>Assumptions!$B$6,"",SUMIFS(Trips!$E$5:$E$1004,Trips!$L$5:$L$1004,$A10)) -> 19 | E10: =IF($A10>Assumptions!$B$6,"",IF(C10=0,0,D10/C10)) -> 0.31666667 | F10: =IF($A10>Assumptions!$B$6,"",COUNTIFS(Trips!$L$5:$L$1004,$A10)) -> 4 | G10: =IF($A10>Assumptions!$B$6,"",SUMIFS(Trips!$F$5:$F$1004,Trips!$L$5:$L$1004,$A10)) -> 1206 | H10: =IF($A10>Assumptions!$B$6,"",SUMIFS(Trips!$H$5:$H$1004,Trips!$L$5:$L$1004,$A10)+SUMIFS(Trips!$I$5:$I$1004,Trips!$L$5:$L$1004,$A10)) -> 994.8 | I10: =IF($A10>Assumptions!$B$6,"",SUMIFS(Trips!$J$5:$J$1004,Trips!$L$5:$L$1004,$A10)+SUMIFS(Expenses!$E$5:$E$1004,Expenses!$G$5:$G$1004,$A10)) -> 323 | J10: =IF($A10>Assumptions!$B$6,"",SUMPRODUCT(((Fleet!$A$5:$A$79<>"")*(Fleet!$E$5:$E$79<=EOMONTH($A10,0))*(((Fleet!$F$5:$F$79="")+(Fleet!$F$5:$F$79>=$A10))>0))*Fleet!$O$5:$O$79)) -> 965 | K10: =IF($A10>Assumptions!$B$6,"",H10-I10-J10) -> -293.2 | L10: =IF($A10>Assumptions!$B$6,"",IF(B10=0,0,K10/B10)) -> -146.6 | M10: =IF($A10>Assumptions!$B$6,"",K10*12) -> -3518.4 | N10: =IF($A10>Assumptions!$B$6,"",IF(L10<=0,"n/a",Assumptions!$B$4/12/L10)) -> n/a
A11: =EDATE(A10,1) -> 46357 | B11: =IF($A11>Assumptions!$B$6,"",SUMPRODUCT(((Fleet!$A$5:$A$79<>"")*(Fleet!$E$5:$E$79<=EOMONTH($A11,0))*(((Fleet!$F$5:$F$79="")+(Fleet!$F$5:$F$79>=$A11))>0)))) | C11: =IF($A11>Assumptions!$B$6,"",B11*DAY(EOMONTH($A11,0))) | D11: =IF($A11>Assumptions!$B$6,"",SUMIFS(Trips!$E$5:$E$1004,Trips!$L$5:$L$1004,$A11)) | E11: =IF($A11>Assumptions!$B$6,"",IF(C11=0,0,D11/C11)) | F11: =IF($A11>Assumptions!$B$6,"",COUNTIFS(Trips!$L$5:$L$1004,$A11)) | G11: =IF($A11>Assumptions!$B$6,"",SUMIFS(Trips!$F$5:$F$1004,Trips!$L$5:$L$1004,$A11)) | H11: =IF($A11>Assumptions!$B$6,"",SUMIFS(Trips!$H$5:$H$1004,Trips!$L$5:$L$1004,$A11)+SUMIFS(Trips!$I$5:$I$1004,Trips!$L$5:$L$1004,$A11)) | I11: =IF($A11>Assumptions!$B$6,"",SUMIFS(Trips!$J$5:$J$1004,Trips!$L$5:$L$1004,$A11)+SUMIFS(Expenses!$E$5:$E$1004,Expenses!$G$5:$G$1004,$A11)) | J11: =IF($A11>Assumptions!$B$6,"",SUMPRODUCT(((Fleet!$A$5:$A$79<>"")*(Fleet!$E$5:$E$79<=EOMONTH($A11,0))*(((Fleet!$F$5:$F$79="")+(Fleet!$F$5:$F$79>=$A11))>0))*Fleet!$O$5:$O$79)) | K11: =IF($A11>Assumptions!$B$6,"",H11-I11-J11) | L11: =IF($A11>Assumptions!$B$6,"",IF(B11=0,0,K11/B11)) | M11: =IF($A11>Assumptions!$B$6,"",K11*12) | N11: =IF($A11>Assumptions!$B$6,"",IF(L11<=0,"n/a",Assumptions!$B$4/12/L11))
A12: =EDATE(A11,1) -> 46388 | B12: =IF($A12>Assumptions!$B$6,"",SUMPRODUCT(((Fleet!$A$5:$A$79<>"")*(Fleet!$E$5:$E$79<=EOMONTH($A12,0))*(((Fleet!$F$5:$F$79="")+(Fleet!$F$5:$F$79>=$A12))>0)))) | C12: =IF($A12>Assumptions!$B$6,"",B12*DAY(EOMONTH($A12,0))) | D12: =IF($A12>Assumptions!$B$6,"",SUMIFS(Trips!$E$5:$E$1004,Trips!$L$5:$L$1004,$A12)) | E12: =IF($A12>Assumptions!$B$6,"",IF(C12=0,0,D12/C12)) | F12: =IF($A12>Assumptions!$B$6,"",COUNTIFS(Trips!$L$5:$L$1004,$A12)) | G12: =IF($A12>Assumptions!$B$6,"",SUMIFS(Trips!$F$5:$F$1004,Trips!$L$5:$L$1004,$A12)) | H12: =IF($A12>Assumptions!$B$6,"",SUMIFS(Trips!$H$5:$H$1004,Trips!$L$5:$L$1004,$A12)+SUMIFS(Trips!$I$5:$I$1004,Trips!$L$5:$L$1004,$A12)) | I12: =IF($A12>Assumptions!$B$6,"",SUMIFS(Trips!$J$5:$J$1004,Trips!$L$5:$L$1004,$A12)+SUMIFS(Expenses!$E$5:$E$1004,Expenses!$G$5:$G$1004,$A12)) | J12: =IF($A12>Assumptions!$B$6,"",SUMPRODUCT(((Fleet!$A$5:$A$79<>"")*(Fleet!$E$5:$E$79<=EOMONTH($A12,0))*(((Fleet!$F$5:$F$79="")+(Fleet!$F$5:$F$79>=$A12))>0))*Fleet!$O$5:$O$79)) | K12: =IF($A12>Assumptions!$B$6,"",H12-I12-J12) | L12: =IF($A12>Assumptions!$B$6,"",IF(B12=0,0,K12/B12)) | M12: =IF($A12>Assumptions!$B$6,"",K12*12) | N12: =IF($A12>Assumptions!$B$6,"",IF(L12<=0,"n/a",Assumptions!$B$4/12/L12))
A13: =EDATE(A12,1) -> 46419 | B13: =IF($A13>Assumptions!$B$6,"",SUMPRODUCT(((Fleet!$A$5:$A$79<>"")*(Fleet!$E$5:$E$79<=EOMONTH($A13,0))*(((Fleet!$F$5:$F$79="")+(Fleet!$F$5:$F$79>=$A13))>0)))) | C13: =IF($A13>Assumptions!$B$6,"",B13*DAY(EOMONTH($A13,0))) | D13: =IF($A13>Assumptions!$B$6,"",SUMIFS(Trips!$E$5:$E$1004,Trips!$L$5:$L$1004,$A13)) | E13: =IF($A13>Assumptions!$B$6,"",IF(C13=0,0,D13/C13)) | F13: =IF($A13>Assumptions!$B$6,"",COUNTIFS(Trips!$L$5:$L$1004,$A13)) | G13: =IF($A13>Assumptions!$B$6,"",SUMIFS(Trips!$F$5:$F$1004,Trips!$L$5:$L$1004,$A13)) | H13: =IF($A13>Assumptions!$B$6,"",SUMIFS(Trips!$H$5:$H$1004,Trips!$L$5:$L$1004,$A13)+SUMIFS(Trips!$I$5:$I$1004,Trips!$L$5:$L$1004,$A13)) | I13: =IF($A13>Assumptions!$B$6,"",SUMIFS(Trips!$J$5:$J$1004,Trips!$L$5:$L$1004,$A13)+SUMIFS(Expenses!$E$5:$E$1004,Expenses!$G$5:$G$1004,$A13)) | J13: =IF($A13>Assumptions!$B$6,"",SUMPRODUCT(((Fleet!$A$5:$A$79<>"")*(Fleet!$E$5:$E$79<=EOMONTH($A13,0))*(((Fleet!$F$5:$F$79="")+(Fleet!$F$5:$F$79>=$A13))>0))*Fleet!$O$5:$O$79)) | K13: =IF($A13>Assumptions!$B$6,"",H13-I13-J13) | L13: =IF($A13>Assumptions!$B$6,"",IF(B13=0,0,K13/B13)) | M13: =IF($A13>Assumptions!$B$6,"",K13*12) | N13: =IF($A13>Assumptions!$B$6,"",IF(L13<=0,"n/a",Assumptions!$B$4/12/L13))
A14: =EDATE(A13,1) -> 46447 | B14: =IF($A14>Assumptions!$B$6,"",SUMPRODUCT(((Fleet!$A$5:$A$79<>"")*(Fleet!$E$5:$E$79<=EOMONTH($A14,0))*(((Fleet!$F$5:$F$79="")+(Fleet!$F$5:$F$79>=$A14))>0)))) | C14: =IF($A14>Assumptions!$B$6,"",B14*DAY(EOMONTH($A14,0))) | D14: =IF($A14>Assumptions!$B$6,"",SUMIFS(Trips!$E$5:$E$1004,Trips!$L$5:$L$1004,$A14)) | E14: =IF($A14>Assumptions!$B$6,"",IF(C14=0,0,D14/C14)) | F14: =IF($A14>Assumptions!$B$6,"",COUNTIFS(Trips!$L$5:$L$1004,$A14)) | G14: =IF($A14>Assumptions!$B$6,"",SUMIFS(Trips!$F$5:$F$1004,Trips!$L$5:$L$1004,$A14)) | H14: =IF($A14>Assumptions!$B$6,"",SUMIFS(Trips!$H$5:$H$1004,Trips!$L$5:$L$1004,$A14)+SUMIFS(Trips!$I$5:$I$1004,Trips!$L$5:$L$1004,$A14)) | I14: =IF($A14>Assumptions!$B$6,"",SUMIFS(Trips!$J$5:$J$1004,Trips!$L$5:$L$1004,$A14)+SUMIFS(Expenses!$E$5:$E$1004,Expenses!$G$5:$G$1004,$A14)) | J14: =IF($A14>Assumptions!$B$6,"",SUMPRODUCT(((Fleet!$A$5:$A$79<>"")*(Fleet!$E$5:$E$79<=EOMONTH($A14,0))*(((Fleet!$F$5:$F$79="")+(Fleet!$F$5:$F$79>=$A14))>0))*Fleet!$O$5:$O$79)) | K14: =IF($A14>Assumptions!$B$6,"",H14-I14-J14) | L14: =IF($A14>Assumptions!$B$6,"",IF(B14=0,0,K14/B14)) | M14: =IF($A14>Assumptions!$B$6,"",K14*12) | N14: =IF($A14>Assumptions!$B$6,"",IF(L14<=0,"n/a",Assumptions!$B$4/12/L14))
A15: =EDATE(A14,1) -> 46478 | B15: =IF($A15>Assumptions!$B$6,"",SUMPRODUCT(((Fleet!$A$5:$A$79<>"")*(Fleet!$E$5:$E$79<=EOMONTH($A15,0))*(((Fleet!$F$5:$F$79="")+(Fleet!$F$5:$F$79>=$A15))>0)))) | C15: =IF($A15>Assumptions!$B$6,"",B15*DAY(EOMONTH($A15,0))) | D15: =IF($A15>Assumptions!$B$6,"",SUMIFS(Trips!$E$5:$E$1004,Trips!$L$5:$L$1004,$A15)) | E15: =IF($A15>Assumptions!$B$6,"",IF(C15=0,0,D15/C15)) | F15: =IF($A15>Assumptions!$B$6,"",COUNTIFS(Trips!$L$5:$L$1004,$A15)) | G15: =IF($A15>Assumptions!$B$6,"",SUMIFS(Trips!$F$5:$F$1004,Trips!$L$5:$L$1004,$A15)) | H15: =IF($A15>Assumptions!$B$6,"",SUMIFS(Trips!$H$5:$H$1004,Trips!$L$5:$L$1004,$A15)+SUMIFS(Trips!$I$5:$I$1004,Trips!$L$5:$L$1004,$A15)) | I15: =IF($A15>Assumptions!$B$6,"",SUMIFS(Trips!$J$5:$J$1004,Trips!$L$5:$L$1004,$A15)+SUMIFS(Expenses!$E$5:$E$1004,Expenses!$G$5:$G$1004,$A15)) | J15: =IF($A15>Assumptions!$B$6,"",SUMPRODUCT(((Fleet!$A$5:$A$79<>"")*(Fleet!$E$5:$E$79<=EOMONTH($A15,0))*(((Fleet!$F$5:$F$79="")+(Fleet!$F$5:$F$79>=$A15))>0))*Fleet!$O$5:$O$79)) | K15: =IF($A15>Assumptions!$B$6,"",H15-I15-J15) | L15: =IF($A15>Assumptions!$B$6,"",IF(B15=0,0,K15/B15)) | M15: =IF($A15>Assumptions!$B$6,"",K15*12) | N15: =IF($A15>Assumptions!$B$6,"",IF(L15<=0,"n/a",Assumptions!$B$4/12/L15))
A16: =EDATE(A15,1) -> 46508 | B16: =IF($A16>Assumptions!$B$6,"",SUMPRODUCT(((Fleet!$A$5:$A$79<>"")*(Fleet!$E$5:$E$79<=EOMONTH($A16,0))*(((Fleet!$F$5:$F$79="")+(Fleet!$F$5:$F$79>=$A16))>0)))) | C16: =IF($A16>Assumptions!$B$6,"",B16*DAY(EOMONTH($A16,0))) | D16: =IF($A16>Assumptions!$B$6,"",SUMIFS(Trips!$E$5:$E$1004,Trips!$L$5:$L$1004,$A16)) | E16: =IF($A16>Assumptions!$B$6,"",IF(C16=0,0,D16/C16)) | F16: =IF($A16>Assumptions!$B$6,"",COUNTIFS(Trips!$L$5:$L$1004,$A16)) | G16: =IF($A16>Assumptions!$B$6,"",SUMIFS(Trips!$F$5:$F$1004,Trips!$L$5:$L$1004,$A16)) | H16: =IF($A16>Assumptions!$B$6,"",SUMIFS(Trips!$H$5:$H$1004,Trips!$L$5:$L$1004,$A16)+SUMIFS(Trips!$I$5:$I$1004,Trips!$L$5:$L$1004,$A16)) | I16: =IF($A16>Assumptions!$B$6,"",SUMIFS(Trips!$J$5:$J$1004,Trips!$L$5:$L$1004,$A16)+SUMIFS(Expenses!$E$5:$E$1004,Expenses!$G$5:$G$1004,$A16)) | J16: =IF($A16>Assumptions!$B$6,"",SUMPRODUCT(((Fleet!$A$5:$A$79<>"")*(Fleet!$E$5:$E$79<=EOMONTH($A16,0))*(((Fleet!$F$5:$F$79="")+(Fleet!$F$5:$F$79>=$A16))>0))*Fleet!$O$5:$O$79)) | K16: =IF($A16>Assumptions!$B$6,"",H16-I16-J16) | L16: =IF($A16>Assumptions!$B$6,"",IF(B16=0,0,K16/B16)) | M16: =IF($A16>Assumptions!$B$6,"",K16*12) | N16: =IF($A16>Assumptions!$B$6,"",IF(L16<=0,"n/a",Assumptions!$B$4/12/L16))
A17: =EDATE(A16,1) -> 46539 | B17: =IF($A17>Assumptions!$B$6,"",SUMPRODUCT(((Fleet!$A$5:$A$79<>"")*(Fleet!$E$5:$E$79<=EOMONTH($A17,0))*(((Fleet!$F$5:$F$79="")+(Fleet!$F$5:$F$79>=$A17))>0)))) | C17: =IF($A17>Assumptions!$B$6,"",B17*DAY(EOMONTH($A17,0))) | D17: =IF($A17>Assumptions!$B$6,"",SUMIFS(Trips!$E$5:$E$1004,Trips!$L$5:$L$1004,$A17)) | E17: =IF($A17>Assumptions!$B$6,"",IF(C17=0,0,D17/C17)) | F17: =IF($A17>Assumptions!$B$6,"",COUNTIFS(Trips!$L$5:$L$1004,$A17)) | G17: =IF($A17>Assumptions!$B$6,"",SUMIFS(Trips!$F$5:$F$1004,Trips!$L$5:$L$1004,$A17)) | H17: =IF($A17>Assumptions!$B$6,"",SUMIFS(Trips!$H$5:$H$1004,Trips!$L$5:$L$1004,$A17)+SUMIFS(Trips!$I$5:$I$1004,Trips!$L$5:$L$1004,$A17)) | I17: =IF($A17>Assumptions!$B$6,"",SUMIFS(Trips!$J$5:$J$1004,Trips!$L$5:$L$1004,$A17)+SUMIFS(Expenses!$E$5:$E$1004,Expenses!$G$5:$G$1004,$A17)) | J17: =IF($A17>Assumptions!$B$6,"",SUMPRODUCT(((Fleet!$A$5:$A$79<>"")*(Fleet!$E$5:$E$79<=EOMONTH($A17,0))*(((Fleet!$F$5:$F$79="")+(Fleet!$F$5:$F$79>=$A17))>0))*Fleet!$O$5:$O$79)) | K17: =IF($A17>Assumptions!$B$6,"",H17-I17-J17) | L17: =IF($A17>Assumptions!$B$6,"",IF(B17=0,0,K17/B17)) | M17: =IF($A17>Assumptions!$B$6,"",K17*12) | N17: =IF($A17>Assumptions!$B$6,"",IF(L17<=0,"n/a",Assumptions!$B$4/12/L17))
A18: =EDATE(A17,1) -> 46569 | B18: =IF($A18>Assumptions!$B$6,"",SUMPRODUCT(((Fleet!$A$5:$A$79<>"")*(Fleet!$E$5:$E$79<=EOMONTH($A18,0))*(((Fleet!$F$5:$F$79="")+(Fleet!$F$5:$F$79>=$A18))>0)))) | C18: =IF($A18>Assumptions!$B$6,"",B18*DAY(EOMONTH($A18,0))) | D18: =IF($A18>Assumptions!$B$6,"",SUMIFS(Trips!$E$5:$E$1004,Trips!$L$5:$L$1004,$A18)) | E18: =IF($A18>Assumptions!$B$6,"",IF(C18=0,0,D18/C18)) | F18: =IF($A18>Assumptions!$B$6,"",COUNTIFS(Trips!$L$5:$L$1004,$A18)) | G18: =IF($A18>Assumptions!$B$6,"",SUMIFS(Trips!$F$5:$F$1004,Trips!$L$5:$L$1004,$A18)) | H18: =IF($A18>Assumptions!$B$6,"",SUMIFS(Trips!$H$5:$H$1004,Trips!$L$5:$L$1004,$A18)+SUMIFS(Trips!$I$5:$I$1004,Trips!$L$5:$L$1004,$A18)) | I18: =IF($A18>Assumptions!$B$6,"",SUMIFS(Trips!$J$5:$J$1004,Trips!$L$5:$L$1004,$A18)+SUMIFS(Expenses!$E$5:$E$1004,Expenses!$G$5:$G$1004,$A18)) | J18: =IF($A18>Assumptions!$B$6,"",SUMPRODUCT(((Fleet!$A$5:$A$79<>"")*(Fleet!$E$5:$E$79<=EOMONTH($A18,0))*(((Fleet!$F$5:$F$79="")+(Fleet!$F$5:$F$79>=$A18))>0))*Fleet!$O$5:$O$79)) | K18: =IF($A18>Assumptions!$B$6,"",H18-I18-J18) | L18: =IF($A18>Assumptions!$B$6,"",IF(B18=0,0,K18/B18)) | M18: =IF($A18>Assumptions!$B$6,"",K18*12) | N18: =IF($A18>Assumptions!$B$6,"",IF(L18<=0,"n/a",Assumptions!$B$4/12/L18))
A19: =EDATE(A18,1) -> 46600 | B19: =IF($A19>Assumptions!$B$6,"",SUMPRODUCT(((Fleet!$A$5:$A$79<>"")*(Fleet!$E$5:$E$79<=EOMONTH($A19,0))*(((Fleet!$F$5:$F$79="")+(Fleet!$F$5:$F$79>=$A19))>0)))) | C19: =IF($A19>Assumptions!$B$6,"",B19*DAY(EOMONTH($A19,0))) | D19: =IF($A19>Assumptions!$B$6,"",SUMIFS(Trips!$E$5:$E$1004,Trips!$L$5:$L$1004,$A19)) | E19: =IF($A19>Assumptions!$B$6,"",IF(C19=0,0,D19/C19)) | F19: =IF($A19>Assumptions!$B$6,"",COUNTIFS(Trips!$L$5:$L$1004,$A19)) | G19: =IF($A19>Assumptions!$B$6,"",SUMIFS(Trips!$F$5:$F$1004,Trips!$L$5:$L$1004,$A19)) | H19: =IF($A19>Assumptions!$B$6,"",SUMIFS(Trips!$H$5:$H$1004,Trips!$L$5:$L$1004,$A19)+SUMIFS(Trips!$I$5:$I$1004,Trips!$L$5:$L$1004,$A19)) | I19: =IF($A19>Assumptions!$B$6,"",SUMIFS(Trips!$J$5:$J$1004,Trips!$L$5:$L$1004,$A19)+SUMIFS(Expenses!$E$5:$E$1004,Expenses!$G$5:$G$1004,$A19)) | J19: =IF($A19>Assumptions!$B$6,"",SUMPRODUCT(((Fleet!$A$5:$A$79<>"")*(Fleet!$E$5:$E$79<=EOMONTH($A19,0))*(((Fleet!$F$5:$F$79="")+(Fleet!$F$5:$F$79>=$A19))>0))*Fleet!$O$5:$O$79)) | K19: =IF($A19>Assumptions!$B$6,"",H19-I19-J19) | L19: =IF($A19>Assumptions!$B$6,"",IF(B19=0,0,K19/B19)) | M19: =IF($A19>Assumptions!$B$6,"",K19*12) | N19: =IF($A19>Assumptions!$B$6,"",IF(L19<=0,"n/a",Assumptions!$B$4/12/L19))
A20: =EDATE(A19,1) -> 46631 | B20: =IF($A20>Assumptions!$B$6,"",SUMPRODUCT(((Fleet!$A$5:$A$79<>"")*(Fleet!$E$5:$E$79<=EOMONTH($A20,0))*(((Fleet!$F$5:$F$79="")+(Fleet!$F$5:$F$79>=$A20))>0)))) | C20: =IF($A20>Assumptions!$B$6,"",B20*DAY(EOMONTH($A20,0))) | D20: =IF($A20>Assumptions!$B$6,"",SUMIFS(Trips!$E$5:$E$1004,Trips!$L$5:$L$1004,$A20)) | E20: =IF($A20>Assumptions!$B$6,"",IF(C20=0,0,D20/C20)) | F20: =IF($A20>Assumptions!$B$6,"",COUNTIFS(Trips!$L$5:$L$1004,$A20)) | G20: =IF($A20>Assumptions!$B$6,"",SUMIFS(Trips!$F$5:$F$1004,Trips!$L$5:$L$1004,$A20)) | H20: =IF($A20>Assumptions!$B$6,"",SUMIFS(Trips!$H$5:$H$1004,Trips!$L$5:$L$1004,$A20)+SUMIFS(Trips!$I$5:$I$1004,Trips!$L$5:$L$1004,$A20)) | I20: =IF($A20>Assumptions!$B$6,"",SUMIFS(Trips!$J$5:$J$1004,Trips!$L$5:$L$1004,$A20)+SUMIFS(Expenses!$E$5:$E$1004,Expenses!$G$5:$G$1004,$A20)) | J20: =IF($A20>Assumptions!$B$6,"",SUMPRODUCT(((Fleet!$A$5:$A$79<>"")*(Fleet!$E$5:$E$79<=EOMONTH($A20,0))*(((Fleet!$F$5:$F$79="")+(Fleet!$F$5:$F$79>=$A20))>0))*Fleet!$O$5:$O$79)) | K20: =IF($A20>Assumptions!$B$6,"",H20-I20-J20) | L20: =IF($A20>Assumptions!$B$6,"",IF(B20=0,0,K20/B20)) | M20: =IF($A20>Assumptions!$B$6,"",K20*12) | N20: =IF($A20>Assumptions!$B$6,"",IF(L20<=0,"n/a",Assumptions!$B$4/12/L20))
A21: =EDATE(A20,1) -> 46661 | B21: =IF($A21>Assumptions!$B$6,"",SUMPRODUCT(((Fleet!$A$5:$A$79<>"")*(Fleet!$E$5:$E$79<=EOMONTH($A21,0))*(((Fleet!$F$5:$F$79="")+(Fleet!$F$5:$F$79>=$A21))>0)))) | C21: =IF($A21>Assumptions!$B$6,"",B21*DAY(EOMONTH($A21,0))) | D21: =IF($A21>Assumptions!$B$6,"",SUMIFS(Trips!$E$5:$E$1004,Trips!$L$5:$L$1004,$A21)) | E21: =IF($A21>Assumptions!$B$6,"",IF(C21=0,0,D21/C21)) | F21: =IF($A21>Assumptions!$B$6,"",COUNTIFS(Trips!$L$5:$L$1004,$A21)) | G21: =IF($A21>Assumptions!$B$6,"",SUMIFS(Trips!$F$5:$F$1004,Trips!$L$5:$L$1004,$A21)) | H21: =IF($A21>Assumptions!$B$6,"",SUMIFS(Trips!$H$5:$H$1004,Trips!$L$5:$L$1004,$A21)+SUMIFS(Trips!$I$5:$I$1004,Trips!$L$5:$L$1004,$A21)) | I21: =IF($A21>Assumptions!$B$6,"",SUMIFS(Trips!$J$5:$J$1004,Trips!$L$5:$L$1004,$A21)+SUMIFS(Expenses!$E$5:$E$1004,Expenses!$G$5:$G$1004,$A21)) | J21: =IF($A21>Assumptions!$B$6,"",SUMPRODUCT(((Fleet!$A$5:$A$79<>"")*(Fleet!$E$5:$E$79<=EOMONTH($A21,0))*(((Fleet!$F$5:$F$79="")+(Fleet!$F$5:$F$79>=$A21))>0))*Fleet!$O$5:$O$79)) | K21: =IF($A21>Assumptions!$B$6,"",H21-I21-J21) | L21: =IF($A21>Assumptions!$B$6,"",IF(B21=0,0,K21/B21)) | M21: =IF($A21>Assumptions!$B$6,"",K21*12) | N21: =IF($A21>Assumptions!$B$6,"",IF(L21<=0,"n/a",Assumptions!$B$4/12/L21))
A22: 12-mo total | C22: =SUM(C10:C21) -> 60 | D22: =SUM(D10:D21) -> 19 | E22: =IF(C22=0,0,D22/C22) -> 0.31666667 | F22: =SUM(F10:F21) -> 4 | G22: =SUM(G10:G21) -> 1206 | H22: =SUM(H10:H21) -> 994.8 | I22: =SUM(I10:I21) -> 323 | J22: =SUM(J10:J21) -> 965 | K22: =SUM(K10:K21) -> -293.2

Sheet Assumptions
A1: Assumptions & targets
A2: Change the yellow cells. Everything else recalculates.
A4: Annual net profit goal ($) | B4: 300000 | C4: Your target (from the plan).
A5: Tracker start month | B5: 46327 | C5: First month on the Dashboard. Use the 1st of a month.
A6: Report month (latest closed month) | B6: 46327 | C6: Car Scorecard reports on this month; Dashboard shows months up to it. Move it forward each month. Use the 1st of a month.
A7: Default host share | B7: 0.8 | C7: Used when a car's plan is blank. US plans: 70% / 80% / 90% (Turo help centre, earnings plans, Jan 2026).
A8: Target utilization | B8: 0.6 | C8: ≈18 booked days a month. Turo's published US average is ~15 days/month (turo.com/list-your-car).
A9: Target net per car per month ($) | B9: 350 | C9: Stage-1 gate from the plan. ~$500 is the well-run-fleet benchmark needed for $300k at ~50 cars.
A10: Max payback (months) | B10: 30 | C10: Buy Box rule: car must repay its price from operating cash flow within this many months.
A11: Cash reserve per car (months of costs) | B11: 2 | C11: Keep this many months of each car's fixed + variable cost in the bank.

Sheet Lists
A1: Expense categories | B1: Car IDs + FLEET
A2: Maintenance | B2: FLEET
A3: Tires | B3: =IF(Fleet!A5="","",Fleet!A5) -> CAR-01
A4: Repairs / damage | B4: =IF(Fleet!A6="","",Fleet!A6) -> CAR-02
A5: Cleaning supplies | B5: =IF(Fleet!A7="","",Fleet!A7)
A6: Detailing | B6: =IF(Fleet!A8="","",Fleet!A8)
A7: Tolls / parking | B7: =IF(Fleet!A9="","",Fleet!A9)
A8: Fuel / charging | B8: =IF(Fleet!A10="","",Fleet!A10)
A9: Software / subscriptions | B9: =IF(Fleet!A11="","",Fleet!A11)
A10: Marketing | B10: =IF(Fleet!A12="","",Fleet!A12)
A11: Labor / contractor | B11: =IF(Fleet!A13="","",Fleet!A13)
A12: Delivery | B12: =IF(Fleet!A14="","",Fleet!A14)
A13: Other | B13: =IF(Fleet!A15="","",Fleet!A15)
B14: =IF(Fleet!A16="","",Fleet!A16)
B15: =IF(Fleet!A17="","",Fleet!A17)
B16: =IF(Fleet!A18="","",Fleet!A18)
B17: =IF(Fleet!A19="","",Fleet!A19)
B18: =IF(Fleet!A20="","",Fleet!A20)
B19: =IF(Fleet!A21="","",Fleet!A21)
B20: =IF(Fleet!A22="","",Fleet!A22)
B21: =IF(Fleet!A23="","",Fleet!A23)
B22: =IF(Fleet!A24="","",Fleet!A24)
B23: =IF(Fleet!A25="","",Fleet!A25)
B24: =IF(Fleet!A26="","",Fleet!A26)
B25: =IF(Fleet!A27="","",Fleet!A27)
... B77: =IF(Fleet!A79="","",Fleet!A79)

Sheet Fleet
A1: Fleet register
A2: One row per car. Fixed monthly costs live here. Leave Sold date blank while you own the car.
A4: Car ID | B4: Year | C4: Make / model | D4: Status | E4: Purchase date | F4: Sold date | G4: Purchase price ($) | H4: Cash invested ($) (down pmt, or full price if cash) | I4: Loan payment ($/mo) | J4: Insurance ($/mo) | K4: Registration ($/yr) | L4: Tracker & software ($/mo) | M4: Parking ($/mo) | N4: Earnings plan host share | O4: Fixed cost ($/mo) | P4: Notes
A5: CAR-01 | B5: 2022 | C5: Toyota Corolla LE | D5: Active | E5: 46327 | G5: 18500 | H5: 3700 | I5: 295 | J5: 110 | K5: 240 | L5: 25 | M5: 0 | N5: 0.8 | O5: =IF(A5="",0,N(I5)+N(J5)+N(K5)/12+N(L5)+N(M5)) -> 450 | P5: EXAMPLE – delete
A6: CAR-02 | B6: 2021 | C6: Toyota RAV4 Hybrid | D6: Active | E6: 46341 | G6: 24000 | H6: 6000 | I6: 335 | J6: 130 | K6: 300 | L6: 25 | M6: 0 | N6: 0.8 | O6: =IF(A6="",0,N(I6)+N(J6)+N(K6)/12+N(L6)+N(M6)) -> 515 | P6: EXAMPLE – delete
O7: =IF(A7="",0,N(I7)+N(J7)+N(K7)/12+N(L7)+N(M7)) -> 0
O8: =IF(A8="",0,N(I8)+N(J8)+N(K8)/12+N(L8)+N(M8)) -> 0
O9: =IF(A9="",0,N(I9)+N(J9)+N(K9)/12+N(L9)+N(M9)) -> 0
O10: =IF(A10="",0,N(I10)+N(J10)+N(K10)/12+N(L10)+N(M10)) -> 0
O11: =IF(A11="",0,N(I11)+N(J11)+N(K11)/12+N(L11)+N(M11)) -> 0
O12: =IF(A12="",0,N(I12)+N(J12)+N(K12)/12+N(L12)+N(M12)) -> 0
O13: =IF(A13="",0,N(I13)+N(J13)+N(K13)/12+N(L13)+N(M13)) -> 0
O14: =IF(A14="",0,N(I14)+N(J14)+N(K14)/12+N(L14)+N(M14)) -> 0
O15: =IF(A15="",0,N(I15)+N(J15)+N(K15)/12+N(L15)+N(M15)) -> 0
O16: =IF(A16="",0,N(I16)+N(J16)+N(K16)/12+N(L16)+N(M16)) -> 0
O17: =IF(A17="",0,N(I17)+N(J17)+N(K17)/12+N(L17)+N(M17)) -> 0
O18: =IF(A18="",0,N(I18)+N(J18)+N(K18)/12+N(L18)+N(M18)) -> 0
... O79: =IF(A79="",0,N(I79)+N(J79)+N(K79)/12+N(L79)+N(M79)) -> 0

Sheet Trips
A1: Trip log
A2: Copy from your Turo earnings export. Trip price = price before Turo's cut. Grey columns are formulas.
A4: Trip ID | B4: Car ID | C4: Start date | D4: End date | E4: Days | F4: Trip price ($) | G4: Host share | H4: Host earnings ($) | I4: Reimbursements & extras ($) (tolls, fuel, delivery) | J4: Turnover cost ($) (clean, fuel, labor) | K4: Guest rating (1–5) | L4: Month | M4: Net trip ($) | N4: Notes
A5: T-1001 | B5: CAR-01 | C5: 46329 | D5: 46333 | E5: =IF(OR(C5="",D5=""),"",MAX(1,D5-C5)) -> 4 | F5: 248 | G5: =IF(B5="","",IFERROR(IF(N(INDEX(Fleet!$N$5:$N$79,MATCH(B5,Fleet!$A$5:$A$79,0)))>0,INDEX(Fleet!$N$5:$N$79,MATCH(B5,Fleet!$A$5:$A$79,0)),Assumptions!$B$7),Assumptions!$B$7)) -> 0.8 | H5: =IF(OR(F5="",G5=""),"",F5*G5) -> 198.4 | I5: 0 | J5: 35 | K5: 5 | L5: =IF(C5="","",DATE(YEAR(C5),MONTH(C5),1)) -> 46327 | M5: =IF(F5="","",N(H5)+N(I5)-N(J5)) -> 163.4 | N5: EXAMPLE – delete
A6: T-1002 | B6: CAR-01 | C6: 46335 | D6: 46342 | E6: =IF(OR(C6="",D6=""),"",MAX(1,D6-C6)) -> 7 | F6: 410 | G6: =IF(B6="","",IFERROR(IF(N(INDEX(Fleet!$N$5:$N$79,MATCH(B6,Fleet!$A$5:$A$79,0)))>0,INDEX(Fleet!$N$5:$N$79,MATCH(B6,Fleet!$A$5:$A$79,0)),Assumptions!$B$7),Assumptions!$B$7)) -> 0.8 | H6: =IF(OR(F6="",G6=""),"",F6*G6) -> 328 | I6: 18 | J6: 35 | K6: 5 | L6: =IF(C6="","",DATE(YEAR(C6),MONTH(C6),1)) -> 46327 | M6: =IF(F6="","",N(H6)+N(I6)-N(J6)) -> 311 | N6: EXAMPLE – delete
A7: T-1003 | B7: CAR-02 | C7: 46344 | D7: 46348 | E7: =IF(OR(C7="",D7=""),"",MAX(1,D7-C7)) -> 4 | F7: 312 | G7: =IF(B7="","",IFERROR(IF(N(INDEX(Fleet!$N$5:$N$79,MATCH(B7,Fleet!$A$5:$A$79,0)))>0,INDEX(Fleet!$N$5:$N$79,MATCH(B7,Fleet!$A$5:$A$79,0)),Assumptions!$B$7),Assumptions!$B$7)) -> 0.8 | H7: =IF(OR(F7="",G7=""),"",F7*G7) -> 249.6 | I7: 0 | J7: 35 | K7: 5 | L7: =IF(C7="","",DATE(YEAR(C7),MONTH(C7),1)) -> 46327 | M7: =IF(F7="","",N(H7)+N(I7)-N(J7)) -> 214.6 | N7: EXAMPLE – delete
A8: T-1004 | B8: CAR-01 | C8: 46346 | D8: 46350 | E8: =IF(OR(C8="",D8=""),"",MAX(1,D8-C8)) -> 4 | F8: 236 | G8: =IF(B8="","",IFERROR(IF(N(INDEX(Fleet!$N$5:$N$79,MATCH(B8,Fleet!$A$5:$A$79,0)))>0,INDEX(Fleet!$N$5:$N$79,MATCH(B8,Fleet!$A$5:$A$79,0)),Assumptions!$B$7),Assumptions!$B$7)) -> 0.8 | H8: =IF(OR(F8="",G8=""),"",F8*G8) -> 188.8 | I8: 12 | J8: 35 | K8: 4 | L8: =IF(C8="","",DATE(YEAR(C8),MONTH(C8),1)) -> 46327 | M8: =IF(F8="","",N(H8)+N(I8)-N(J8)) -> 165.8 | N8: EXAMPLE – delete
E9: =IF(OR(C9="",D9=""),"",MAX(1,D9-C9)) | G9: =IF(B9="","",IFERROR(IF(N(INDEX(Fleet!$N$5:$N$79,MATCH(B9,Fleet!$A$5:$A$79,0)))>0,INDEX(Fleet!$N$5:$N$79,MATCH(B9,Fleet!$A$5:$A$79,0)),Assumptions!$B$7),Assumptions!$B$7)) | H9: =IF(OR(F9="",G9=""),"",F9*G9) | L9: =IF(C9="","",DATE(YEAR(C9),MONTH(C9),1)) | M9: =IF(F9="","",N(H9)+N(I9)-N(J9))
E10: =IF(OR(C10="",D10=""),"",MAX(1,D10-C10)) | G10: =IF(B10="","",IFERROR(IF(N(INDEX(Fleet!$N$5:$N$79,MATCH(B10,Fleet!$A$5:$A$79,0)))>0,INDEX(Fleet!$N$5:$N$79,MATCH(B10,Fleet!$A$5:$A$79,0)),Assumptions!$B$7),Assumptions!$B$7)) | H10: =IF(OR(F10="",G10=""),"",F10*G10) | L10: =IF(C10="","",DATE(YEAR(C10),MONTH(C10),1)) | M10: =IF(F10="","",N(H10)+N(I10)-N(J10))
E11: =IF(OR(C11="",D11=""),"",MAX(1,D11-C11)) | G11: =IF(B11="","",IFERROR(IF(N(INDEX(Fleet!$N$5:$N$79,MATCH(B11,Fleet!$A$5:$A$79,0)))>0,INDEX(Fleet!$N$5:$N$79,MATCH(B11,Fleet!$A$5:$A$79,0)),Assumptions!$B$7),Assumptions!$B$7)) | H11: =IF(OR(F11="",G11=""),"",F11*G11) | L11: =IF(C11="","",DATE(YEAR(C11),MONTH(C11),1)) | M11: =IF(F11="","",N(H11)+N(I11)-N(J11))
E12: =IF(OR(C12="",D12=""),"",MAX(1,D12-C12)) | G12: =IF(B12="","",IFERROR(IF(N(INDEX(Fleet!$N$5:$N$79,MATCH(B12,Fleet!$A$5:$A$79,0)))>0,INDEX(Fleet!$N$5:$N$79,MATCH(B12,Fleet!$A$5:$A$79,0)),Assumptions!$B$7),Assumptions!$B$7)) | H12: =IF(OR(F12="",G12=""),"",F12*G12) | L12: =IF(C12="","",DATE(YEAR(C12),MONTH(C12),1)) | M12: =IF(F12="","",N(H12)+N(I12)-N(J12))
E13: =IF(OR(C13="",D13=""),"",MAX(1,D13-C13)) | G13: =IF(B13="","",IFERROR(IF(N(INDEX(Fleet!$N$5:$N$79,MATCH(B13,Fleet!$A$5:$A$79,0)))>0,INDEX(Fleet!$N$5:$N$79,MATCH(B13,Fleet!$A$5:$A$79,0)),Assumptions!$B$7),Assumptions!$B$7)) | H13: =IF(OR(F13="",G13=""),"",F13*G13) | L13: =IF(C13="","",DATE(YEAR(C13),MONTH(C13),1)) | M13: =IF(F13="","",N(H13)+N(I13)-N(J13))
E14: =IF(OR(C14="",D14=""),"",MAX(1,D14-C14)) | G14: =IF(B14="","",IFERROR(IF(N(INDEX(Fleet!$N$5:$N$79,MATCH(B14,Fleet!$A$5:$A$79,0)))>0,INDEX(Fleet!$N$5:$N$79,MATCH(B14,Fleet!$A$5:$A$79,0)),Assumptions!$B$7),Assumptions!$B$7)) | H14: =IF(OR(F14="",G14=""),"",F14*G14) | L14: =IF(C14="","",DATE(YEAR(C14),MONTH(C14),1)) | M14: =IF(F14="","",N(H14)+N(I14)-N(J14))
E15: =IF(OR(C15="",D15=""),"",MAX(1,D15-C15)) | G15: =IF(B15="","",IFERROR(IF(N(INDEX(Fleet!$N$5:$N$79,MATCH(B15,Fleet!$A$5:$A$79,0)))>0,INDEX(Fleet!$N$5:$N$79,MATCH(B15,Fleet!$A$5:$A$79,0)),Assumptions!$B$7),Assumptions!$B$7)) | H15: =IF(OR(F15="",G15=""),"",F15*G15) | L15: =IF(C15="","",DATE(YEAR(C15),MONTH(C15),1)) | M15: =IF(F15="","",N(H15)+N(I15)-N(J15))
E16: =IF(OR(C16="",D16=""),"",MAX(1,D16-C16)) | G16: =IF(B16="","",IFERROR(IF(N(INDEX(Fleet!$N$5:$N$79,MATCH(B16,Fleet!$A$5:$A$79,0)))>0,INDEX(Fleet!$N$5:$N$79,MATCH(B16,Fleet!$A$5:$A$79,0)),Assumptions!$B$7),Assumptions!$B$7)) | H16: =IF(OR(F16="",G16=""),"",F16*G16) | L16: =IF(C16="","",DATE(YEAR(C16),MONTH(C16),1)) | M16: =IF(F16="","",N(H16)+N(I16)-N(J16))
E17: =IF(OR(C17="",D17=""),"",MAX(1,D17-C17)) | G17: =IF(B17="","",IFERROR(IF(N(INDEX(Fleet!$N$5:$N$79,MATCH(B17,Fleet!$A$5:$A$79,0)))>0,INDEX(Fleet!$N$5:$N$79,MATCH(B17,Fleet!$A$5:$A$79,0)),Assumptions!$B$7),Assumptions!$B$7)) | H17: =IF(OR(F17="",G17=""),"",F17*G17) | L17: =IF(C17="","",DATE(YEAR(C17),MONTH(C17),1)) | M17: =IF(F17="","",N(H17)+N(I17)-N(J17))
E18: =IF(OR(C18="",D18=""),"",MAX(1,D18-C18)) | G18: =IF(B18="","",IFERROR(IF(N(INDEX(Fleet!$N$5:$N$79,MATCH(B18,Fleet!$A$5:$A$79,0)))>0,INDEX(Fleet!$N$5:$N$79,MATCH(B18,Fleet!$A$5:$A$79,0)),Assumptions!$B$7),Assumptions!$B$7)) | H18: =IF(OR(F18="",G18=""),"",F18*G18) | L18: =IF(C18="","",DATE(YEAR(C18),MONTH(C18),1)) | M18: =IF(F18="","",N(H18)+N(I18)-N(J18))
E19: =IF(OR(C19="",D19=""),"",MAX(1,D19-C19)) | G19: =IF(B19="","",IFERROR(IF(N(INDEX(Fleet!$N$5:$N$79,MATCH(B19,Fleet!$A$5:$A$79,0)))>0,INDEX(Fleet!$N$5:$N$79,MATCH(B19,Fleet!$A$5:$A$79,0)),Assumptions!$B$7),Assumptions!$B$7)) | H19: =IF(OR(F19="",G19=""),"",F19*G19) | L19: =IF(C19="","",DATE(YEAR(C19),MONTH(C19),1)) | M19: =IF(F19="","",N(H19)+N(I19)-N(J19))
E20: =IF(OR(C20="",D20=""),"",MAX(1,D20-C20)) | G20: =IF(B20="","",IFERROR(IF(N(INDEX(Fleet!$N$5:$N$79,MATCH(B20,Fleet!$A$5:$A$79,0)))>0,INDEX(Fleet!$N$5:$N$79,MATCH(B20,Fleet!$A$5:$A$79,0)),Assumptions!$B$7),Assumptions!$B$7)) | H20: =IF(OR(F20="",G20=""),"",F20*G20) | L20: =IF(C20="","",DATE(YEAR(C20),MONTH(C20),1)) | M20: =IF(F20="","",N(H20)+N(I20)-N(J20))
... E1004: =IF(OR(C1004="",D1004=""),"",MAX(1,D1004-C1004)) | G1004: =IF(B1004="","",IFERROR(IF(N(INDEX(Fleet!$N$5:$N$79,MATCH(B1004,Fleet!$A$5:$A$79,0)))>0,INDEX(Fleet!$N$5:$N$79,MATCH(B1004,Fleet!$A$5:$A$79,0)),Assumptions!$B$7),Assumptions!$B$7)) | H1004: =IF(OR(F1004="",G1004=""),"",F1004*G1004) | L1004: =IF(C1004="","",DATE(YEAR(C1004),MONTH(C1004),1)) | M1004: =IF(F1004="","",N(H1004)+N(I1004)-N(J1004))

Sheet Expenses
A1: Variable expenses
A2: Do NOT log loan, insurance, registration, tracker or parking here — those are fixed costs on the Fleet tab.
A4: Date | B4: Car ID (or FLEET) | C4: Category | D4: Vendor | E4: Amount ($) | F4: Notes | G4: Month
A5: 46328 | B5: FLEET | C5: Cleaning supplies | D5: Costco | E5: 64 | F5: EXAMPLE – delete | G5: =IF(A5="","",DATE(YEAR(A5),MONTH(A5),1)) -> 46327
A6: 46343 | B6: CAR-01 | C6: Maintenance | D6: Quick Lube | E6: 79 | F6: EXAMPLE – delete | G6: =IF(A6="","",DATE(YEAR(A6),MONTH(A6),1)) -> 46327
A7: 46351 | B7: FLEET | C7: Software / subscriptions | D7: Pricing tool | E7: 40 | F7: EXAMPLE – delete | G7: =IF(A7="","",DATE(YEAR(A7),MONTH(A7),1)) -> 46327
G8: =IF(A8="","",DATE(YEAR(A8),MONTH(A8),1))
G9: =IF(A9="","",DATE(YEAR(A9),MONTH(A9),1))
G10: =IF(A10="","",DATE(YEAR(A10),MONTH(A10),1))
G11: =IF(A11="","",DATE(YEAR(A11),MONTH(A11),1))
G12: =IF(A12="","",DATE(YEAR(A12),MONTH(A12),1))
G13: =IF(A13="","",DATE(YEAR(A13),MONTH(A13),1))
G14: =IF(A14="","",DATE(YEAR(A14),MONTH(A14),1))
G15: =IF(A15="","",DATE(YEAR(A15),MONTH(A15),1))
G16: =IF(A16="","",DATE(YEAR(A16),MONTH(A16),1))
G17: =IF(A17="","",DATE(YEAR(A17),MONTH(A17),1))
G18: =IF(A18="","",DATE(YEAR(A18),MONTH(A18),1))
G19: =IF(A19="","",DATE(YEAR(A19),MONTH(A19),1))
... G1004: =IF(A1004="","",DATE(YEAR(A1004),MONTH(A1004),1))

Sheet Car Scorecard
A1: Car scorecard
A2: Reports on the Report month set on the Assumptions tab.
A3: Month: | B3: =Assumptions!$B$6 -> 46327
A5: Car ID | B5: Make / model | C5: Owned this month | D5: Booked days | E5: Utilization | F5: Earnings + extras ($) | G5: Variable costs ($) | H5: Fixed cost ($) | I5: Net this month ($) | J5: Net last month ($) | K5: Net 2 months ago ($) | L5: Lifetime net ($) | M5: Cash invested ($) | N5: Payback progress | O5: Flag
A6: =IF(Fleet!A5="","",Fleet!A5) -> CAR-01 | B6: =IF(Fleet!A5="","",Fleet!B5&" "&Fleet!C5) -> 2022 Toyota Corolla LE | C6: =IF($A6="","",IF(AND(Fleet!$A$5<>"",N(Fleet!$E$5)<=EOMONTH($B$3,0),OR(Fleet!$F$5="",N(Fleet!$F$5)>=$B$3)),1,0)) -> 1 | D6: =IF($A6="","",SUMIFS(Trips!$E$5:$E$1004,Trips!$B$5:$B$1004,$A6,Trips!$L$5:$L$1004,$B$3)) -> 15 | E6: =IF(OR($A6="",N(C6)=0),"",D6/DAY(EOMONTH($B$3,0))) -> 0.5 | F6: =IF($A6="","",SUMIFS(Trips!$H$5:$H$1004,Trips!$B$5:$B$1004,$A6,Trips!$L$5:$L$1004,$B$3)+SUMIFS(Trips!$I$5:$I$1004,Trips!$B$5:$B$1004,$A6,Trips!$L$5:$L$1004,$B$3)) -> 745.2 | G6: =IF($A6="","",SUMIFS(Trips!$J$5:$J$1004,Trips!$B$5:$B$1004,$A6,Trips!$L$5:$L$1004,$B$3)+SUMIFS(Expenses!$E$5:$E$1004,Expenses!$B$5:$B$1004,$A6,Expenses!$G$5:$G$1004,$B$3)) -> 184 | H6: =IF($A6="","",Fleet!$O$5*C6) -> 450 | I6: =IF($A6="","",F6-G6-H6) -> 111.2 | J6: =IF($A6="","",(SUMIFS(Trips!$H$5:$H$1004,Trips!$B$5:$B$1004,$A6,Trips!$L$5:$L$1004,EDATE($B$3,-1))+SUMIFS(Trips!$I$5:$I$1004,Trips!$B$5:$B$1004,$A6,Trips!$L$5:$L$1004,EDATE($B$3,-1))-SUMIFS(Trips!$J$5:$J$1004,Trips!$B$5:$B$1004,$A6,Trips!$L$5:$L$1004,EDATE($B$3,-1))-SUMIFS(Expenses!$E$5:$E$1004,Expenses!$B$5:$B$1004,$A6,Expenses!$G$5:$G$1004,EDATE($B$3,-1))-Fleet!$O$5*IF(AND(Fleet!$A$5<>"",N(Fleet!$E$5)<=EOMONTH(EDATE($B$3,-1),0),OR(Fleet!$F$5="",N(Fleet!$F$5)>=EDATE($B$3,-1))),1,0))) -> 0 | K6: =IF($A6="","",(SUMIFS(Trips!$H$5:$H$1004,Trips!$B$5:$B$1004,$A6,Trips!$L$5:$L$1004,EDATE($B$3,-2))+SUMIFS(Trips!$I$5:$I$1004,Trips!$B$5:$B$1004,$A6,Trips!$L$5:$L$1004,EDATE($B$3,-2))-SUMIFS(Trips!$J$5:$J$1004,Trips!$B$5:$B$1004,$A6,Trips!$L$5:$L$1004,EDATE($B$3,-2))-SUMIFS(Expenses!$E$5:$E$1004,Expenses!$B$5:$B$1004,$A6,Expenses!$G$5:$G$1004,EDATE($B$3,-2))-Fleet!$O$5*IF(AND(Fleet!$A$5<>"",N(Fleet!$E$5)<=EOMONTH(EDATE($B$3,-2),0),OR(Fleet!$F$5="",N(Fleet!$F$5)>=EDATE($B$3,-2))),1,0))) -> 0 | L6: =IF($A6="","",SUMIFS(Trips!$M$5:$M$1004,Trips!$B$5:$B$1004,$A6,Trips!$L$5:$L$1004,"<="&$B$3)-SUMIFS(Expenses!$E$5:$E$1004,Expenses!$B$5:$B$1004,$A6,Expenses!$G$5:$G$1004,"<="&$B$3)-Fleet!$O$5*IF(N(Fleet!$E$5)=0,0,MAX(0,(YEAR(IF(Fleet!$F$5="",EOMONTH($B$3,0),MIN(Fleet!$F$5,EOMONTH($B$3,0))))-YEAR(Fleet!$E$5))*12+MONTH(IF(Fleet!$F$5="",EOMONTH($B$3,0),MIN(Fleet!$F$5,EOMONTH($B$3,0))))-MONTH(Fleet!$E$5)+1))) -> 111.2 | M6: =IF($A6="","",Fleet!$H$5) -> 3700 | N6: =IF(OR($A6="",N(M6)=0),"",L6/M6) -> 0.030054054 | O6: =IF(OR($A6="",N(C6)=0),"",IF(AND(I6<0,J6<0,K6<0),"REVIEW: 3 losing months",IF(I6<Assumptions!$B$9,"Below net target",IF(E6<Assumptions!$B$8,"Low utilization","On track")))) -> Below net target
A7: =IF(Fleet!A6="","",Fleet!A6) -> CAR-02 | B7: =IF(Fleet!A6="","",Fleet!B6&" "&Fleet!C6) -> 2021 Toyota RAV4 Hybrid | C7: =IF($A7="","",IF(AND(Fleet!$A$6<>"",N(Fleet!$E$6)<=EOMONTH($B$3,0),OR(Fleet!$F$6="",N(Fleet!$F$6)>=$B$3)),1,0)) -> 1 | D7: =IF($A7="","",SUMIFS(Trips!$E$5:$E$1004,Trips!$B$5:$B$1004,$A7,Trips!$L$5:$L$1004,$B$3)) -> 4 | E7: =IF(OR($A7="",N(C7)=0),"",D7/DAY(EOMONTH($B$3,0))) -> 0.13333333 | F7: =IF($A7="","",SUMIFS(Trips!$H$5:$H$1004,Trips!$B$5:$B$1004,$A7,Trips!$L$5:$L$1004,$B$3)+SUMIFS(Trips!$I$5:$I$1004,Trips!$B$5:$B$1004,$A7,Trips!$L$5:$L$1004,$B$3)) -> 249.6 | G7: =IF($A7="","",SUMIFS(Trips!$J$5:$J$1004,Trips!$B$5:$B$1004,$A7,Trips!$L$5:$L$1004,$B$3)+SUMIFS(Expenses!$E$5:$E$1004,Expenses!$B$5:$B$1004,$A7,Expenses!$G$5:$G$1004,$B$3)) -> 35 | H7: =IF($A7="","",Fleet!$O$6*C7) -> 515 | I7: =IF($A7="","",F7-G7-H7) -> -300.4 | J7: =IF($A7="","",(SUMIFS(Trips!$H$5:$H$1004,Trips!$B$5:$B$1004,$A7,Trips!$L$5:$L$1004,EDATE($B$3,-1))+SUMIFS(Trips!$I$5:$I$1004,Trips!$B$5:$B$1004,$A7,Trips!$L$5:$L$1004,EDATE($B$3,-1))-SUMIFS(Trips!$J$5:$J$1004,Trips!$B$5:$B$1004,$A7,Trips!$L$5:$L$1004,EDATE($B$3,-1))-SUMIFS(Expenses!$E$5:$E$1004,Expenses!$B$5:$B$1004,$A7,Expenses!$G$5:$G$1004,EDATE($B$3,-1))-Fleet!$O$6*IF(AND(Fleet!$A$6<>"",N(Fleet!$E$6)<=EOMONTH(EDATE($B$3,-1),0),OR(Fleet!$F$6="",N(Fleet!$F$6)>=EDATE($B$3,-1))),1,0))) -> 0 | K7: =IF($A7="","",(SUMIFS(Trips!$H$5:$H$1004,Trips!$B$5:$B$1004,$A7,Trips!$L$5:$L$1004,EDATE($B$3,-2))+SUMIFS(Trips!$I$5:$I$1004,Trips!$B$5:$B$1004,$A7,Trips!$L$5:$L$1004,EDATE($B$3,-2))-SUMIFS(Trips!$J$5:$J$1004,Trips!$B$5:$B$1004,$A7,Trips!$L$5:$L$1004,EDATE($B$3,-2))-SUMIFS(Expenses!$E$5:$E$1004,Expenses!$B$5:$B$1004,$A7,Expenses!$G$5:$G$1004,EDATE($B$3,-2))-Fleet!$O$6*IF(AND(Fleet!$A$6<>"",N(Fleet!$E$6)<=EOMONTH(EDATE($B$3,-2),0),OR(Fleet!$F$6="",N(Fleet!$F$6)>=EDATE($B$3,-2))),1,0))) -> 0 | L7: =IF($A7="","",SUMIFS(Trips!$M$5:$M$1004,Trips!$B$5:$B$1004,$A7,Trips!$L$5:$L$1004,"<="&$B$3)-SUMIFS(Expenses!$E$5:$E$1004,Expenses!$B$5:$B$1004,$A7,Expenses!$G$5:$G$1004,"<="&$B$3)-Fleet!$O$6*IF(N(Fleet!$E$6)=0,0,MAX(0,(YEAR(IF(Fleet!$F$6="",EOMONTH($B$3,0),MIN(Fleet!$F$6,EOMONTH($B$3,0))))-YEAR(Fleet!$E$6))*12+MONTH(IF(Fleet!$F$6="",EOMONTH($B$3,0),MIN(Fleet!$F$6,EOMONTH($B$3,0))))-MONTH(Fleet!$E$6)+1))) -> -300.4 | M7: =IF($A7="","",Fleet!$H$6) -> 6000 | N7: =IF(OR($A7="",N(M7)=0),"",L7/M7) -> -0.050066667 | O7: =IF(OR($A7="",N(C7)=0),"",IF(AND(I7<0,J7<0,K7<0),"REVIEW: 3 losing months",IF(I7<Assumptions!$B$9,"Below net target",IF(E7<Assumptions!$B$8,"Low utilization","On track")))) -> Below net target
A8: =IF(Fleet!A7="","",Fleet!A7) | B8: =IF(Fleet!A7="","",Fleet!B7&" "&Fleet!C7) | C8: =IF($A8="","",IF(AND(Fleet!$A$7<>"",N(Fleet!$E$7)<=EOMONTH($B$3,0),OR(Fleet!$F$7="",N(Fleet!$F$7)>=$B$3)),1,0)) | D8: =IF($A8="","",SUMIFS(Trips!$E$5:$E$1004,Trips!$B$5:$B$1004,$A8,Trips!$L$5:$L$1004,$B$3)) | E8: =IF(OR($A8="",N(C8)=0),"",D8/DAY(EOMONTH($B$3,0))) | F8: =IF($A8="","",SUMIFS(Trips!$H$5:$H$1004,Trips!$B$5:$B$1004,$A8,Trips!$L$5:$L$1004,$B$3)+SUMIFS(Trips!$I$5:$I$1004,Trips!$B$5:$B$1004,$A8,Trips!$L$5:$L$1004,$B$3)) | G8: =IF($A8="","",SUMIFS(Trips!$J$5:$J$1004,Trips!$B$5:$B$1004,$A8,Trips!$L$5:$L$1004,$B$3)+SUMIFS(Expenses!$E$5:$E$1004,Expenses!$B$5:$B$1004,$A8,Expenses!$G$5:$G$1004,$B$3)) | H8: =IF($A8="","",Fleet!$O$7*C8) | I8: =IF($A8="","",F8-G8-H8) | J8: =IF($A8="","",(SUMIFS(Trips!$H$5:$H$1004,Trips!$B$5:$B$1004,$A8,Trips!$L$5:$L$1004,EDATE($B$3,-1))+SUMIFS(Trips!$I$5:$I$1004,Trips!$B$5:$B$1004,$A8,Trips!$L$5:$L$1004,EDATE($B$3,-1))-SUMIFS(Trips!$J$5:$J$1004,Trips!$B$5:$B$1004,$A8,Trips!$L$5:$L$1004,EDATE($B$3,-1))-SUMIFS(Expenses!$E$5:$E$1004,Expenses!$B$5:$B$1004,$A8,Expenses!$G$5:$G$1004,EDATE($B$3,-1))-Fleet!$O$7*IF(AND(Fleet!$A$7<>"",N(Fleet!$E$7)<=EOMONTH(EDATE($B$3,-1),0),OR(Fleet!$F$7="",N(Fleet!$F$7)>=EDATE($B$3,-1))),1,0))) | K8: =IF($A8="","",(SUMIFS(Trips!$H$5:$H$1004,Trips!$B$5:$B$1004,$A8,Trips!$L$5:$L$1004,EDATE($B$3,-2))+SUMIFS(Trips!$I$5:$I$1004,Trips!$B$5:$B$1004,$A8,Trips!$L$5:$L$1004,EDATE($B$3,-2))-SUMIFS(Trips!$J$5:$J$1004,Trips!$B$5:$B$1004,$A8,Trips!$L$5:$L$1004,EDATE($B$3,-2))-SUMIFS(Expenses!$E$5:$E$1004,Expenses!$B$5:$B$1004,$A8,Expenses!$G$5:$G$1004,EDATE($B$3,-2))-Fleet!$O$7*IF(AND(Fleet!$A$7<>"",N(Fleet!$E$7)<=EOMONTH(EDATE($B$3,-2),0),OR(Fleet!$F$7="",N(Fleet!$F$7)>=EDATE($B$3,-2))),1,0))) | L8: =IF($A8="","",SUMIFS(Trips!$M$5:$M$1004,Trips!$B$5:$B$1004,$A8,Trips!$L$5:$L$1004,"<="&$B$3)-SUMIFS(Expenses!$E$5:$E$1004,Expenses!$B$5:$B$1004,$A8,Expenses!$G$5:$G$1004,"<="&$B$3)-Fleet!$O$7*IF(N(Fleet!$E$7)=0,0,MAX(0,(YEAR(IF(Fleet!$F$7="",EOMONTH($B$3,0),MIN(Fleet!$F$7,EOMONTH($B$3,0))))-YEAR(Fleet!$E$7))*12+MONTH(IF(Fleet!$F$7="",EOMONTH($B$3,0),MIN(Fleet!$F$7,EOMONTH($B$3,0))))-MONTH(Fleet!$E$7)+1))) | M8: =IF($A8="","",Fleet!$H$7) | N8: =IF(OR($A8="",N(M8)=0),"",L8/M8) | O8: =IF(OR($A8="",N(C8)=0),"",IF(AND(I8<0,J8<0,K8<0),"REVIEW: 3 losing months",IF(I8<Assumptions!$B$9,"Below net target",IF(E8<Assumptions!$B$8,"Low utilization","On track"))))
A9: =IF(Fleet!A8="","",Fleet!A8) | B9: =IF(Fleet!A8="","",Fleet!B8&" "&Fleet!C8) | C9: =IF($A9="","",IF(AND(Fleet!$A$8<>"",N(Fleet!$E$8)<=EOMONTH($B$3,0),OR(Fleet!$F$8="",N(Fleet!$F$8)>=$B$3)),1,0)) | D9: =IF($A9="","",SUMIFS(Trips!$E$5:$E$1004,Trips!$B$5:$B$1004,$A9,Trips!$L$5:$L$1004,$B$3)) | E9: =IF(OR($A9="",N(C9)=0),"",D9/DAY(EOMONTH($B$3,0))) | F9: =IF($A9="","",SUMIFS(Trips!$H$5:$H$1004,Trips!$B$5:$B$1004,$A9,Trips!$L$5:$L$1004,$B$3)+SUMIFS(Trips!$I$5:$I$1004,Trips!$B$5:$B$1004,$A9,Trips!$L$5:$L$1004,$B$3)) | G9: =IF($A9="","",SUMIFS(Trips!$J$5:$J$1004,Trips!$B$5:$B$1004,$A9,Trips!$L$5:$L$1004,$B$3)+SUMIFS(Expenses!$E$5:$E$1004,Expenses!$B$5:$B$1004,$A9,Expenses!$G$5:$G$1004,$B$3)) | H9: =IF($A9="","",Fleet!$O$8*C9) | I9: =IF($A9="","",F9-G9-H9) | J9: =IF($A9="","",(SUMIFS(Trips!$H$5:$H$1004,Trips!$B$5:$B$1004,$A9,Trips!$L$5:$L$1004,EDATE($B$3,-1))+SUMIFS(Trips!$I$5:$I$1004,Trips!$B$5:$B$1004,$A9,Trips!$L$5:$L$1004,EDATE($B$3,-1))-SUMIFS(Trips!$J$5:$J$1004,Trips!$B$5:$B$1004,$A9,Trips!$L$5:$L$1004,EDATE($B$3,-1))-SUMIFS(Expenses!$E$5:$E$1004,Expenses!$B$5:$B$1004,$A9,Expenses!$G$5:$G$1004,EDATE($B$3,-1))-Fleet!$O$8*IF(AND(Fleet!$A$8<>"",N(Fleet!$E$8)<=EOMONTH(EDATE($B$3,-1),0),OR(Fleet!$F$8="",N(Fleet!$F$8)>=EDATE($B$3,-1))),1,0))) | K9: =IF($A9="","",(SUMIFS(Trips!$H$5:$H$1004,Trips!$B$5:$B$1004,$A9,Trips!$L$5:$L$1004,EDATE($B$3,-2))+SUMIFS(Trips!$I$5:$I$1004,Trips!$B$5:$B$1004,$A9,Trips!$L$5:$L$1004,EDATE($B$3,-2))-SUMIFS(Trips!$J$5:$J$1004,Trips!$B$5:$B$1004,$A9,Trips!$L$5:$L$1004,EDATE($B$3,-2))-SUMIFS(Expenses!$E$5:$E$1004,Expenses!$B$5:$B$1004,$A9,Expenses!$G$5:$G$1004,EDATE($B$3,-2))-Fleet!$O$8*IF(AND(Fleet!$A$8<>"",N(Fleet!$E$8)<=EOMONTH(EDATE($B$3,-2),0),OR(Fleet!$F$8="",N(Fleet!$F$8)>=EDATE($B$3,-2))),1,0))) | L9: =IF($A9="","",SUMIFS(Trips!$M$5:$M$1004,Trips!$B$5:$B$1004,$A9,Trips!$L$5:$L$1004,"<="&$B$3)-SUMIFS(Expenses!$E$5:$E$1004,Expenses!$B$5:$B$1004,$A9,Expenses!$G$5:$G$1004,"<="&$B$3)-Fleet!$O$8*IF(N(Fleet!$E$8)=0,0,MAX(0,(YEAR(IF(Fleet!$F$8="",EOMONTH($B$3,0),MIN(Fleet!$F$8,EOMONTH($B$3,0))))-YEAR(Fleet!$E$8))*12+MONTH(IF(Fleet!$F$8="",EOMONTH($B$3,0),MIN(Fleet!$F$8,EOMONTH($B$3,0))))-MONTH(Fleet!$E$8)+1))) | M9: =IF($A9="","",Fleet!$H$8) | N9: =IF(OR($A9="",N(M9)=0),"",L9/M9) | O9: =IF(OR($A9="",N(C9)=0),"",IF(AND(I9<0,J9<0,K9<0),"REVIEW: 3 losing months",IF(I9<Assumptions!$B$9,"Below net target",IF(E9<Assumptions!$B$8,"Low utilization","On track"))))
A10: =IF(Fleet!A9="","",Fleet!A9) | B10: =IF(Fleet!A9="","",Fleet!B9&" "&Fleet!C9) | C10: =IF($A10="","",IF(AND(Fleet!$A$9<>"",N(Fleet!$E$9)<=EOMONTH($B$3,0),OR(Fleet!$F$9="",N(Fleet!$F$9)>=$B$3)),1,0)) | D10: =IF($A10="","",SUMIFS(Trips!$E$5:$E$1004,Trips!$B$5:$B$1004,$A10,Trips!$L$5:$L$1004,$B$3)) | E10: =IF(OR($A10="",N(C10)=0),"",D10/DAY(EOMONTH($B$3,0))) | F10: =IF($A10="","",SUMIFS(Trips!$H$5:$H$1004,Trips!$B$5:$B$1004,$A10,Trips!$L$5:$L$1004,$B$3)+SUMIFS(Trips!$I$5:$I$1004,Trips!$B$5:$B$1004,$A10,Trips!$L$5:$L$1004,$B$3)) | G10: =IF($A10="","",SUMIFS(Trips!$J$5:$J$1004,Trips!$B$5:$B$1004,$A10,Trips!$L$5:$L$1004,$B$3)+SUMIFS(Expenses!$E$5:$E$1004,Expenses!$B$5:$B$1004,$A10,Expenses!$G$5:$G$1004,$B$3)) | H10: =IF($A10="","",Fleet!$O$9*C10) | I10: =IF($A10="","",F10-G10-H10) | J10: =IF($A10="","",(SUMIFS(Trips!$H$5:$H$1004,Trips!$B$5:$B$1004,$A10,Trips!$L$5:$L$1004,EDATE($B$3,-1))+SUMIFS(Trips!$I$5:$I$1004,Trips!$B$5:$B$1004,$A10,Trips!$L$5:$L$1004,EDATE($B$3,-1))-SUMIFS(Trips!$J$5:$J$1004,Trips!$B$5:$B$1004,$A10,Trips!$L$5:$L$1004,EDATE($B$3,-1))-SUMIFS(Expenses!$E$5:$E$1004,Expenses!$B$5:$B$1004,$A10,Expenses!$G$5:$G$1004,EDATE($B$3,-1))-Fleet!$O$9*IF(AND(Fleet!$A$9<>"",N(Fleet!$E$9)<=EOMONTH(EDATE($B$3,-1),0),OR(Fleet!$F$9="",N(Fleet!$F$9)>=EDATE($B$3,-1))),1,0))) | K10: =IF($A10="","",(SUMIFS(Trips!$H$5:$H$1004,Trips!$B$5:$B$1004,$A10,Trips!$L$5:$L$1004,EDATE($B$3,-2))+SUMIFS(Trips!$I$5:$I$1004,Trips!$B$5:$B$1004,$A10,Trips!$L$5:$L$1004,EDATE($B$3,-2))-SUMIFS(Trips!$J$5:$J$1004,Trips!$B$5:$B$1004,$A10,Trips!$L$5:$L$1004,EDATE($B$3,-2))-SUMIFS(Expenses!$E$5:$E$1004,Expenses!$B$5:$B$1004,$A10,Expenses!$G$5:$G$1004,EDATE($B$3,-2))-Fleet!$O$9*IF(AND(Fleet!$A$9<>"",N(Fleet!$E$9)<=EOMONTH(EDATE($B$3,-2),0),OR(Fleet!$F$9="",N(Fleet!$F$9)>=EDATE($B$3,-2))),1,0))) | L10: =IF($A10="","",SUMIFS(Trips!$M$5:$M$1004,Trips!$B$5:$B$1004,$A10,Trips!$L$5:$L$1004,"<="&$B$3)-SUMIFS(Expenses!$E$5:$E$1004,Expenses!$B$5:$B$1004,$A10,Expenses!$G$5:$G$1004,"<="&$B$3)-Fleet!$O$9*IF(N(Fleet!$E$9)=0,0,MAX(0,(YEAR(IF(Fleet!$F$9="",EOMONTH($B$3,0),MIN(Fleet!$F$9,EOMONTH($B$3,0))))-YEAR(Fleet!$E$9))*12+MONTH(IF(Fleet!$F$9="",EOMONTH($B$3,0),MIN(Fleet!$F$9,EOMONTH($B$3,0))))-MONTH(Fleet!$E$9)+1))) | M10: =IF($A10="","",Fleet!$H$9) | N10: =IF(OR($A10="",N(M10)=0),"",L10/M10) | O10: =IF(OR($A10="",N(C10)=0),"",IF(AND(I10<0,J10<0,K10<0),"REVIEW: 3 losing months",IF(I10<Assumptions!$B$9,"Below net target",IF(E10<Assumptions!$B$8,"Low utilization","On track"))))
A11: =IF(Fleet!A10="","",Fleet!A10) | B11: =IF(Fleet!A10="","",Fleet!B10&" "&Fleet!C10) | C11: =IF($A11="","",IF(AND(Fleet!$A$10<>"",N(Fleet!$E$10)<=EOMONTH($B$3,0),OR(Fleet!$F$10="",N(Fleet!$F$10)>=$B$3)),1,0)) | D11: =IF($A11="","",SUMIFS(Trips!$E$5:$E$1004,Trips!$B$5:$B$1004,$A11,Trips!$L$5:$L$1004,$B$3)) | E11: =IF(OR($A11="",N(C11)=0),"",D11/DAY(EOMONTH($B$3,0))) | F11: =IF($A11="","",SUMIFS(Trips!$H$5:$H$1004,Trips!$B$5:$B$1004,$A11,Trips!$L$5:$L$1004,$B$3)+SUMIFS(Trips!$I$5:$I$1004,Trips!$B$5:$B$1004,$A11,Trips!$L$5:$L$1004,$B$3)) | G11: =IF($A11="","",SUMIFS(Trips!$J$5:$J$1004,Trips!$B$5:$B$1004,$A11,Trips!$L$5:$L$1004,$B$3)+SUMIFS(Expenses!$E$5:$E$1004,Expenses!$B$5:$B$1004,$A11,Expenses!$G$5:$G$1004,$B$3)) | H11: =IF($A11="","",Fleet!$O$10*C11) | I11: =IF($A11="","",F11-G11-H11) | J11: =IF($A11="","",(SUMIFS(Trips!$H$5:$H$1004,Trips!$B$5:$B$1004,$A11,Trips!$L$5:$L$1004,EDATE($B$3,-1))+SUMIFS(Trips!$I$5:$I$1004,Trips!$B$5:$B$1004,$A11,Trips!$L$5:$L$1004,EDATE($B$3,-1))-SUMIFS(Trips!$J$5:$J$1004,Trips!$B$5:$B$1004,$A11,Trips!$L$5:$L$1004,EDATE($B$3,-1))-SUMIFS(Expenses!$E$5:$E$1004,Expenses!$B$5:$B$1004,$A11,Expenses!$G$5:$G$1004,EDATE($B$3,-1))-Fleet!$O$10*IF(AND(Fleet!$A$10<>"",N(Fleet!$E$10)<=EOMONTH(EDATE($B$3,-1),0),OR(Fleet!$F$10="",N(Fleet!$F$10)>=EDATE($B$3,-1))),1,0))) | K11: =IF($A11="","",(SUMIFS(Trips!$H$5:$H$1004,Trips!$B$5:$B$1004,$A11,Trips!$L$5:$L$1004,EDATE($B$3,-2))+SUMIFS(Trips!$I$5:$I$1004,Trips!$B$5:$B$1004,$A11,Trips!$L$5:$L$1004,EDATE($B$3,-2))-SUMIFS(Trips!$J$5:$J$1004,Trips!$B$5:$B$1004,$A11,Trips!$L$5:$L$1004,EDATE($B$3,-2))-SUMIFS(Expenses!$E$5:$E$1004,Expenses!$B$5:$B$1004,$A11,Expenses!$G$5:$G$1004,EDATE($B$3,-2))-Fleet!$O$10*IF(AND(Fleet!$A$10<>"",N(Fleet!$E$10)<=EOMONTH(EDATE($B$3,-2),0),OR(Fleet!$F$10="",N(Fleet!$F$10)>=EDATE($B$3,-2))),1,0))) | L11: =IF($A11="","",SUMIFS(Trips!$M$5:$M$1004,Trips!$B$5:$B$1004,$A11,Trips!$L$5:$L$1004,"<="&$B$3)-SUMIFS(Expenses!$E$5:$E$1004,Expenses!$B$5:$B$1004,$A11,Expenses!$G$5:$G$1004,"<="&$B$3)-Fleet!$O$10*IF(N(Fleet!$E$10)=0,0,MAX(0,(YEAR(IF(Fleet!$F$10="",EOMONTH($B$3,0),MIN(Fleet!$F$10,EOMONTH($B$3,0))))-YEAR(Fleet!$E$10))*12+MONTH(IF(Fleet!$F$10="",EOMONTH($B$3,0),MIN(Fleet!$F$10,EOMONTH($B$3,0))))-MONTH(Fleet!$E$10)+1))) | M11: =IF($A11="","",Fleet!$H$10) | N11: =IF(OR($A11="",N(M11)=0),"",L11/M11) | O11: =IF(OR($A11="",N(C11)=0),"",IF(AND(I11<0,J11<0,K11<0),"REVIEW: 3 losing months",IF(I11<Assumptions!$B$9,"Below net target",IF(E11<Assumptions!$B$8,"Low utilization","On track"))))
A12: =IF(Fleet!A11="","",Fleet!A11) | B12: =IF(Fleet!A11="","",Fleet!B11&" "&Fleet!C11) | C12: =IF($A12="","",IF(AND(Fleet!$A$11<>"",N(Fleet!$E$11)<=EOMONTH($B$3,0),OR(Fleet!$F$11="",N(Fleet!$F$11)>=$B$3)),1,0)) | D12: =IF($A12="","",SUMIFS(Trips!$E$5:$E$1004,Trips!$B$5:$B$1004,$A12,Trips!$L$5:$L$1004,$B$3)) | E12: =IF(OR($A12="",N(C12)=0),"",D12/DAY(EOMONTH($B$3,0))) | F12: =IF($A12="","",SUMIFS(Trips!$H$5:$H$1004,Trips!$B$5:$B$1004,$A12,Trips!$L$5:$L$1004,$B$3)+SUMIFS(Trips!$I$5:$I$1004,Trips!$B$5:$B$1004,$A12,Trips!$L$5:$L$1004,$B$3)) | G12: =IF($A12="","",SUMIFS(Trips!$J$5:$J$1004,Trips!$B$5:$B$1004,$A12,Trips!$L$5:$L$1004,$B$3)+SUMIFS(Expenses!$E$5:$E$1004,Expenses!$B$5:$B$1004,$A12,Expenses!$G$5:$G$1004,$B$3)) | H12: =IF($A12="","",Fleet!$O$11*C12) | I12: =IF($A12="","",F12-G12-H12) | J12: =IF($A12="","",(SUMIFS(Trips!$H$5:$H$1004,Trips!$B$5:$B$1004,$A12,Trips!$L$5:$L$1004,EDATE($B$3,-1))+SUMIFS(Trips!$I$5:$I$1004,Trips!$B$5:$B$1004,$A12,Trips!$L$5:$L$1004,EDATE($B$3,-1))-SUMIFS(Trips!$J$5:$J$1004,Trips!$B$5:$B$1004,$A12,Trips!$L$5:$L$1004,EDATE($B$3,-1))-SUMIFS(Expenses!$E$5:$E$1004,Expenses!$B$5:$B$1004,$A12,Expenses!$G$5:$G$1004,EDATE($B$3,-1))-Fleet!$O$11*IF(AND(Fleet!$A$11<>"",N(Fleet!$E$11)<=EOMONTH(EDATE($B$3,-1),0),OR(Fleet!$F$11="",N(Fleet!$F$11)>=EDATE($B$3,-1))),1,0))) | K12: =IF($A12="","",(SUMIFS(Trips!$H$5:$H$1004,Trips!$B$5:$B$1004,$A12,Trips!$L$5:$L$1004,EDATE($B$3,-2))+SUMIFS(Trips!$I$5:$I$1004,Trips!$B$5:$B$1004,$A12,Trips!$L$5:$L$1004,EDATE($B$3,-2))-SUMIFS(Trips!$J$5:$J$1004,Trips!$B$5:$B$1004,$A12,Trips!$L$5:$L$1004,EDATE($B$3,-2))-SUMIFS(Expenses!$E$5:$E$1004,Expenses!$B$5:$B$1004,$A12,Expenses!$G$5:$G$1004,EDATE($B$3,-2))-Fleet!$O$11*IF(AND(Fleet!$A$11<>"",N(Fleet!$E$11)<=EOMONTH(EDATE($B$3,-2),0),OR(Fleet!$F$11="",N(Fleet!$F$11)>=EDATE($B$3,-2))),1,0))) | L12: =IF($A12="","",SUMIFS(Trips!$M$5:$M$1004,Trips!$B$5:$B$1004,$A12,Trips!$L$5:$L$1004,"<="&$B$3)-SUMIFS(Expenses!$E$5:$E$1004,Expenses!$B$5:$B$1004,$A12,Expenses!$G$5:$G$1004,"<="&$B$3)-Fleet!$O$11*IF(N(Fleet!$E$11)=0,0,MAX(0,(YEAR(IF(Fleet!$F$11="",EOMONTH($B$3,0),MIN(Fleet!$F$11,EOMONTH($B$3,0))))-YEAR(Fleet!$E$11))*12+MONTH(IF(Fleet!$F$11="",EOMONTH($B$3,0),MIN(Fleet!$F$11,EOMONTH($B$3,0))))-MONTH(Fleet!$E$11)+1))) | M12: =IF($A12="","",Fleet!$H$11) | N12: =IF(OR($A12="",N(M12)=0),"",L12/M12) | O12: =IF(OR($A12="",N(C12)=0),"",IF(AND(I12<0,J12<0,K12<0),"REVIEW: 3 losing months",IF(I12<Assumptions!$B$9,"Below net target",IF(E12<Assumptions!$B$8,"Low utilization","On track"))))
A13: =IF(Fleet!A12="","",Fleet!A12) | B13: =IF(Fleet!A12="","",Fleet!B12&" "&Fleet!C12) | C13: =IF($A13="","",IF(AND(Fleet!$A$12<>"",N(Fleet!$E$12)<=EOMONTH($B$3,0),OR(Fleet!$F$12="",N(Fleet!$F$12)>=$B$3)),1,0)) | D13: =IF($A13="","",SUMIFS(Trips!$E$5:$E$1004,Trips!$B$5:$B$1004,$A13,Trips!$L$5:$L$1004,$B$3)) | E13: =IF(OR($A13="",N(C13)=0),"",D13/DAY(EOMONTH($B$3,0))) | F13: =IF($A13="","",SUMIFS(Trips!$H$5:$H$1004,Trips!$B$5:$B$1004,$A13,Trips!$L$5:$L$1004,$B$3)+SUMIFS(Trips!$I$5:$I$1004,Trips!$B$5:$B$1004,$A13,Trips!$L$5:$L$1004,$B$3)) | G13: =IF($A13="","",SUMIFS(Trips!$J$5:$J$1004,Trips!$B$5:$B$1004,$A13,Trips!$L$5:$L$1004,$B$3)+SUMIFS(Expenses!$E$5:$E$1004,Expenses!$B$5:$B$1004,$A13,Expenses!$G$5:$G$1004,$B$3)) | H13: =IF($A13="","",Fleet!$O$12*C13) | I13: =IF($A13="","",F13-G13-H13) | J13: =IF($A13="","",(SUMIFS(Trips!$H$5:$H$1004,Trips!$B$5:$B$1004,$A13,Trips!$L$5:$L$1004,EDATE($B$3,-1))+SUMIFS(Trips!$I$5:$I$1004,Trips!$B$5:$B$1004,$A13,Trips!$L$5:$L$1004,EDATE($B$3,-1))-SUMIFS(Trips!$J$5:$J$1004,Trips!$B$5:$B$1004,$A13,Trips!$L$5:$L$1004,EDATE($B$3,-1))-SUMIFS(Expenses!$E$5:$E$1004,Expenses!$B$5:$B$1004,$A13,Expenses!$G$5:$G$1004,EDATE($B$3,-1))-Fleet!$O$12*IF(AND(Fleet!$A$12<>"",N(Fleet!$E$12)<=EOMONTH(EDATE($B$3,-1),0),OR(Fleet!$F$12="",N(Fleet!$F$12)>=EDATE($B$3,-1))),1,0))) | K13: =IF($A13="","",(SUMIFS(Trips!$H$5:$H$1004,Trips!$B$5:$B$1004,$A13,Trips!$L$5:$L$1004,EDATE($B$3,-2))+SUMIFS(Trips!$I$5:$I$1004,Trips!$B$5:$B$1004,$A13,Trips!$L$5:$L$1004,EDATE($B$3,-2))-SUMIFS(Trips!$J$5:$J$1004,Trips!$B$5:$B$1004,$A13,Trips!$L$5:$L$1004,EDATE($B$3,-2))-SUMIFS(Expenses!$E$5:$E$1004,Expenses!$B$5:$B$1004,$A13,Expenses!$G$5:$G$1004,EDATE($B$3,-2))-Fleet!$O$12*IF(AND(Fleet!$A$12<>"",N(Fleet!$E$12)<=EOMONTH(EDATE($B$3,-2),0),OR(Fleet!$F$12="",N(Fleet!$F$12)>=EDATE($B$3,-2))),1,0))) | L13: =IF($A13="","",SUMIFS(Trips!$M$5:$M$1004,Trips!$B$5:$B$1004,$A13,Trips!$L$5:$L$1004,"<="&$B$3)-SUMIFS(Expenses!$E$5:$E$1004,Expenses!$B$5:$B$1004,$A13,Expenses!$G$5:$G$1004,"<="&$B$3)-Fleet!$O$12*IF(N(Fleet!$E$12)=0,0,MAX(0,(YEAR(IF(Fleet!$F$12="",EOMONTH($B$3,0),MIN(Fleet!$F$12,EOMONTH($B$3,0))))-YEAR(Fleet!$E$12))*12+MONTH(IF(Fleet!$F$12="",EOMONTH($B$3,0),MIN(Fleet!$F$12,EOMONTH($B$3,0))))-MONTH(Fleet!$E$12)+1))) | M13: =IF($A13="","",Fleet!$H$12) | N13: =IF(OR($A13="",N(M13)=0),"",L13/M13) | O13: =IF(OR($A13="",N(C13)=0),"",IF(AND(I13<0,J13<0,K13<0),"REVIEW: 3 losing months",IF(I13<Assumptions!$B$9,"Below net target",IF(E13<Assumptions!$B$8,"Low utilization","On track"))))
A14: =IF(Fleet!A13="","",Fleet!A13) | B14: =IF(Fleet!A13="","",Fleet!B13&" "&Fleet!C13) | C14: =IF($A14="","",IF(AND(Fleet!$A$13<>"",N(Fleet!$E$13)<=EOMONTH($B$3,0),OR(Fleet!$F$13="",N(Fleet!$F$13)>=$B$3)),1,0)) | D14: =IF($A14="","",SUMIFS(Trips!$E$5:$E$1004,Trips!$B$5:$B$1004,$A14,Trips!$L$5:$L$1004,$B$3)) | E14: =IF(OR($A14="",N(C14)=0),"",D14/DAY(EOMONTH($B$3,0))) | F14: =IF($A14="","",SUMIFS(Trips!$H$5:$H$1004,Trips!$B$5:$B$1004,$A14,Trips!$L$5:$L$1004,$B$3)+SUMIFS(Trips!$I$5:$I$1004,Trips!$B$5:$B$1004,$A14,Trips!$L$5:$L$1004,$B$3)) | G14: =IF($A14="","",SUMIFS(Trips!$J$5:$J$1004,Trips!$B$5:$B$1004,$A14,Trips!$L$5:$L$1004,$B$3)+SUMIFS(Expenses!$E$5:$E$1004,Expenses!$B$5:$B$1004,$A14,Expenses!$G$5:$G$1004,$B$3)) | H14: =IF($A14="","",Fleet!$O$13*C14) | I14: =IF($A14="","",F14-G14-H14) | J14: =IF($A14="","",(SUMIFS(Trips!$H$5:$H$1004,Trips!$B$5:$B$1004,$A14,Trips!$L$5:$L$1004,EDATE($B$3,-1))+SUMIFS(Trips!$I$5:$I$1004,Trips!$B$5:$B$1004,$A14,Trips!$L$5:$L$1004,EDATE($B$3,-1))-SUMIFS(Trips!$J$5:$J$1004,Trips!$B$5:$B$1004,$A14,Trips!$L$5:$L$1004,EDATE($B$3,-1))-SUMIFS(Expenses!$E$5:$E$1004,Expenses!$B$5:$B$1004,$A14,Expenses!$G$5:$G$1004,EDATE($B$3,-1))-Fleet!$O$13*IF(AND(Fleet!$A$13<>"",N(Fleet!$E$13)<=EOMONTH(EDATE($B$3,-1),0),OR(Fleet!$F$13="",N(Fleet!$F$13)>=EDATE($B$3,-1))),1,0))) | K14: =IF($A14="","",(SUMIFS(Trips!$H$5:$H$1004,Trips!$B$5:$B$1004,$A14,Trips!$L$5:$L$1004,EDATE($B$3,-2))+SUMIFS(Trips!$I$5:$I$1004,Trips!$B$5:$B$1004,$A14,Trips!$L$5:$L$1004,EDATE($B$3,-2))-SUMIFS(Trips!$J$5:$J$1004,Trips!$B$5:$B$1004,$A14,Trips!$L$5:$L$1004,EDATE($B$3,-2))-SUMIFS(Expenses!$E$5:$E$1004,Expenses!$B$5:$B$1004,$A14,Expenses!$G$5:$G$1004,EDATE($B$3,-2))-Fleet!$O$13*IF(AND(Fleet!$A$13<>"",N(Fleet!$E$13)<=EOMONTH(EDATE($B$3,-2),0),OR(Fleet!$F$13="",N(Fleet!$F$13)>=EDATE($B$3,-2))),1,0))) | L14: =IF($A14="","",SUMIFS(Trips!$M$5:$M$1004,Trips!$B$5:$B$1004,$A14,Trips!$L$5:$L$1004,"<="&$B$3)-SUMIFS(Expenses!$E$5:$E$1004,Expenses!$B$5:$B$1004,$A14,Expenses!$G$5:$G$1004,"<="&$B$3)-Fleet!$O$13*IF(N(Fleet!$E$13)=0,0,MAX(0,(YEAR(IF(Fleet!$F$13="",EOMONTH($B$3,0),MIN(Fleet!$F$13,EOMONTH($B$3,0))))-YEAR(Fleet!$E$13))*12+MONTH(IF(Fleet!$F$13="",EOMONTH($B$3,0),MIN(Fleet!$F$13,EOMONTH($B$3,0))))-MONTH(Fleet!$E$13)+1))) | M14: =IF($A14="","",Fleet!$H$13) | N14: =IF(OR($A14="",N(M14)=0),"",L14/M14) | O14: =IF(OR($A14="",N(C14)=0),"",IF(AND(I14<0,J14<0,K14<0),"REVIEW: 3 losing months",IF(I14<Assumptions!$B$9,"Below net target",IF(E14<Assumptions!$B$8,"Low utilization","On track"))))
A15: =IF(Fleet!A14="","",Fleet!A14) | B15: =IF(Fleet!A14="","",Fleet!B14&" "&Fleet!C14) | C15: =IF($A15="","",IF(AND(Fleet!$A$14<>"",N(Fleet!$E$14)<=EOMONTH($B$3,0),OR(Fleet!$F$14="",N(Fleet!$F$14)>=$B$3)),1,0)) | D15: =IF($A15="","",SUMIFS(Trips!$E$5:$E$1004,Trips!$B$5:$B$1004,$A15,Trips!$L$5:$L$1004,$B$3)) | E15: =IF(OR($A15="",N(C15)=0),"",D15/DAY(EOMONTH($B$3,0))) | F15: =IF($A15="","",SUMIFS(Trips!$H$5:$H$1004,Trips!$B$5:$B$1004,$A15,Trips!$L$5:$L$1004,$B$3)+SUMIFS(Trips!$I$5:$I$1004,Trips!$B$5:$B$1004,$A15,Trips!$L$5:$L$1004,$B$3)) | G15: =IF($A15="","",SUMIFS(Trips!$J$5:$J$1004,Trips!$B$5:$B$1004,$A15,Trips!$L$5:$L$1004,$B$3)+SUMIFS(Expenses!$E$5:$E$1004,Expenses!$B$5:$B$1004,$A15,Expenses!$G$5:$G$1004,$B$3)) | H15: =IF($A15="","",Fleet!$O$14*C15) | I15: =IF($A15="","",F15-G15-H15) | J15: =IF($A15="","",(SUMIFS(Trips!$H$5:$H$1004,Trips!$B$5:$B$1004,$A15,Trips!$L$5:$L$1004,EDATE($B$3,-1))+SUMIFS(Trips!$I$5:$I$1004,Trips!$B$5:$B$1004,$A15,Trips!$L$5:$L$1004,EDATE($B$3,-1))-SUMIFS(Trips!$J$5:$J$1004,Trips!$B$5:$B$1004,$A15,Trips!$L$5:$L$1004,EDATE($B$3,-1))-SUMIFS(Expenses!$E$5:$E$1004,Expenses!$B$5:$B$1004,$A15,Expenses!$G$5:$G$1004,EDATE($B$3,-1))-Fleet!$O$14*IF(AND(Fleet!$A$14<>"",N(Fleet!$E$14)<=EOMONTH(EDATE($B$3,-1),0),OR(Fleet!$F$14="",N(Fleet!$F$14)>=EDATE($B$3,-1))),1,0))) | K15: =IF($A15="","",(SUMIFS(Trips!$H$5:$H$1004,Trips!$B$5:$B$1004,$A15,Trips!$L$5:$L$1004,EDATE($B$3,-2))+SUMIFS(Trips!$I$5:$I$1004,Trips!$B$5:$B$1004,$A15,Trips!$L$5:$L$1004,EDATE($B$3,-2))-SUMIFS(Trips!$J$5:$J$1004,Trips!$B$5:$B$1004,$A15,Trips!$L$5:$L$1004,EDATE($B$3,-2))-SUMIFS(Expenses!$E$5:$E$1004,Expenses!$B$5:$B$1004,$A15,Expenses!$G$5:$G$1004,EDATE($B$3,-2))-Fleet!$O$14*IF(AND(Fleet!$A$14<>"",N(Fleet!$E$14)<=EOMONTH(EDATE($B$3,-2),0),OR(Fleet!$F$14="",N(Fleet!$F$14)>=EDATE($B$3,-2))),1,0))) | L15: =IF($A15="","",SUMIFS(Trips!$M$5:$M$1004,Trips!$B$5:$B$1004,$A15,Trips!$L$5:$L$1004,"<="&$B$3)-SUMIFS(Expenses!$E$5:$E$1004,Expenses!$B$5:$B$1004,$A15,Expenses!$G$5:$G$1004,"<="&$B$3)-Fleet!$O$14*IF(N(Fleet!$E$14)=0,0,MAX(0,(YEAR(IF(Fleet!$F$14="",EOMONTH($B$3,0),MIN(Fleet!$F$14,EOMONTH($B$3,0))))-YEAR(Fleet!$E$14))*12+MONTH(IF(Fleet!$F$14="",EOMONTH($B$3,0),MIN(Fleet!$F$14,EOMONTH($B$3,0))))-MONTH(Fleet!$E$14)+1))) | M15: =IF($A15="","",Fleet!$H$14) | N15: =IF(OR($A15="",N(M15)=0),"",L15/M15) | O15: =IF(OR($A15="",N(C15)=0),"",IF(AND(I15<0,J15<0,K15<0),"REVIEW: 3 losing months",IF(I15<Assumptions!$B$9,"Below net target",IF(E15<Assumptions!$B$8,"Low utilization","On track"))))
A16: =IF(Fleet!A15="","",Fleet!A15) | B16: =IF(Fleet!A15="","",Fleet!B15&" "&Fleet!C15) | C16: =IF($A16="","",IF(AND(Fleet!$A$15<>"",N(Fleet!$E$15)<=EOMONTH($B$3,0),OR(Fleet!$F$15="",N(Fleet!$F$15)>=$B$3)),1,0)) | D16: =IF($A16="","",SUMIFS(Trips!$E$5:$E$1004,Trips!$B$5:$B$1004,$A16,Trips!$L$5:$L$1004,$B$3)) | E16: =IF(OR($A16="",N(C16)=0),"",D16/DAY(EOMONTH($B$3,0))) | F16: =IF($A16="","",SUMIFS(Trips!$H$5:$H$1004,Trips!$B$5:$B$1004,$A16,Trips!$L$5:$L$1004,$B$3)+SUMIFS(Trips!$I$5:$I$1004,Trips!$B$5:$B$1004,$A16,Trips!$L$5:$L$1004,$B$3)) | G16: =IF($A16="","",SUMIFS(Trips!$J$5:$J$1004,Trips!$B$5:$B$1004,$A16,Trips!$L$5:$L$1004,$B$3)+SUMIFS(Expenses!$E$5:$E$1004,Expenses!$B$5:$B$1004,$A16,Expenses!$G$5:$G$1004,$B$3)) | H16: =IF($A16="","",Fleet!$O$15*C16) | I16: =IF($A16="","",F16-G16-H16) | J16: =IF($A16="","",(SUMIFS(Trips!$H$5:$H$1004,Trips!$B$5:$B$1004,$A16,Trips!$L$5:$L$1004,EDATE($B$3,-1))+SUMIFS(Trips!$I$5:$I$1004,Trips!$B$5:$B$1004,$A16,Trips!$L$5:$L$1004,EDATE($B$3,-1))-SUMIFS(Trips!$J$5:$J$1004,Trips!$B$5:$B$1004,$A16,Trips!$L$5:$L$1004,EDATE($B$3,-1))-SUMIFS(Expenses!$E$5:$E$1004,Expenses!$B$5:$B$1004,$A16,Expenses!$G$5:$G$1004,EDATE($B$3,-1))-Fleet!$O$15*IF(AND(Fleet!$A$15<>"",N(Fleet!$E$15)<=EOMONTH(EDATE($B$3,-1),0),OR(Fleet!$F$15="",N(Fleet!$F$15)>=EDATE($B$3,-1))),1,0))) | K16: =IF($A16="","",(SUMIFS(Trips!$H$5:$H$1004,Trips!$B$5:$B$1004,$A16,Trips!$L$5:$L$1004,EDATE($B$3,-2))+SUMIFS(Trips!$I$5:$I$1004,Trips!$B$5:$B$1004,$A16,Trips!$L$5:$L$1004,EDATE($B$3,-2))-SUMIFS(Trips!$J$5:$J$1004,Trips!$B$5:$B$1004,$A16,Trips!$L$5:$L$1004,EDATE($B$3,-2))-SUMIFS(Expenses!$E$5:$E$1004,Expenses!$B$5:$B$1004,$A16,Expenses!$G$5:$G$1004,EDATE($B$3,-2))-Fleet!$O$15*IF(AND(Fleet!$A$15<>"",N(Fleet!$E$15)<=EOMONTH(EDATE($B$3,-2),0),OR(Fleet!$F$15="",N(Fleet!$F$15)>=EDATE($B$3,-2))),1,0))) | L16: =IF($A16="","",SUMIFS(Trips!$M$5:$M$1004,Trips!$B$5:$B$1004,$A16,Trips!$L$5:$L$1004,"<="&$B$3)-SUMIFS(Expenses!$E$5:$E$1004,Expenses!$B$5:$B$1004,$A16,Expenses!$G$5:$G$1004,"<="&$B$3)-Fleet!$O$15*IF(N(Fleet!$E$15)=0,0,MAX(0,(YEAR(IF(Fleet!$F$15="",EOMONTH($B$3,0),MIN(Fleet!$F$15,EOMONTH($B$3,0))))-YEAR(Fleet!$E$15))*12+MONTH(IF(Fleet!$F$15="",EOMONTH($B$3,0),MIN(Fleet!$F$15,EOMONTH($B$3,0))))-MONTH(Fleet!$E$15)+1))) | M16: =IF($A16="","",Fleet!$H$15) | N16: =IF(OR($A16="",N(M16)=0),"",L16/M16) | O16: =IF(OR($A16="",N(C16)=0),"",IF(AND(I16<0,J16<0,K16<0),"REVIEW: 3 losing months",IF(I16<Assumptions!$B$9,"Below net target",IF(E16<Assumptions!$B$8,"Low utilization","On track"))))
